Workbook
Name _: #REF!
Name __: #REF!
Name ____: #REF!
Name _______A70000: #REF!
Name _______A80000: #REF!
Name _______sh1: #REF!
Name _______SP14: #REF!
Name _______SP15: #REF!
Name _______SP16: #REF!
Name _______SP17: #REF!
Name _______SP18: #REF!
Name _______SP19: #REF!
Name _______SP2: #REF!
Name _______SP20: #REF!
Name _______SP3: #REF!
Name _______SP4: #REF!
Name _______SP5: #REF!
Name _______SP7: #REF!
Name _______SP8: #REF!
Name _______SP9: #REF!
Name ______A70000: #REF!
Name ______A80000: #REF!
Name ______DAT1: #REF!
Name ______DAT10: #REF!
Name ______DAT2: #REF!
Name ______DAT3: #REF!
Name ______DAT4: #REF!
Name ______DAT5: #REF!
Name ______DAT6: #REF!
Name ______DAT7: #REF!
Name ______DAT8: #REF!
Name ______DAT9: #REF!
Name ______END1: #REF!
Name ______END2: #REF!
Name ______END4: #REF!
Name ______END6: #REF!
Name ______END7: #REF!
Name ______IV65900: #REF!
Name ______IV66000: #REF!
Name ______IV69000: #REF!
Name ______IV70000: #REF!
Name ______JA1: #REF!
Name ______KA1: #REF!
Name ______LA1: #REF!
Name ______lp280202: #REF!
Name ______MIF1: #REF!
Name ______MIF2: #REF!
Name ______MIF3: #REF!
Name ______MO33: #REF!
Name ______MO34: #REF!
Name ______MO35: #REF!
Name ______MO36: #REF!
Name ______MO37: #REF!
Name ______MO38: #REF!
Name ______MO39: #REF!
Name ______MO40: #REF!
Name ______MO41: #REF!
Name ______MO42: #REF!
Name ______MO43: #REF!
Name ______MO44: #REF!

Sheet Output
B2: Общие показатели проекта Model Farm Zhailau
A4: х | B4: Ключевые допущения
A6: 1 | B6: Проект финансируется АКК в рамках Национальной программы развития животноводства по целевому назначению: строительство инфраструктуры, закуп маточного поголовья и быков-производителей (долгосрочные займы) и финансирование оборотного капитала (закуп кормов, чипов, прочих расходников, оплата ФОТ пастухам, обязательное страхование). Финансирование оборотного капитала необходимо в течение срока реализации проекта, со сроком погашения - 2 года.
B7: Общая стомость проекта
E8: 1ый год | F8: 2ой год
B9: Капитальные затраты | D9: тыс. тенге | E9: =SUM(E10:E12) -> 302465.15 | F9: =SUM(F10:F12) -> 0
C10: ='Operating Model'!C17 -> Предварительные расходы | D10: тыс. тенге | E10: ='Operating Model'!F17 -> 20000 | F10: ='Operating Model'!G17 -> 0
C11: ='Operating Model'!C18 -> Строительство зданий и инфраструктура | D11: тыс. тенге | E11: ='Operating Model'!F18 -> 224825.15 | F11: ='Operating Model'!G18 -> 0
C12: ='Operating Model'!C19 -> Спецтехника и оборудование | D12: тыс. тенге | E12: ='Operating Model'!F19 -> 57640 | F12: ='Operating Model'!G19 -> 0
B13: Закуп стада | D13: тыс. тенге | E13: =SUM(E14:E16) -> 119100 | F13: =SUM(F14:F16) -> 0
C14: ='Operating Model'!C22 -> Маточное поголовье | D14: тыс. тенге | E14: ='Operating Model'!F22 -> 110000 | F14: ='Operating Model'!G22 -> 0
C15: ='Operating Model'!C23 -> Быки-проивзодители | D15: тыс. тенге | E15: ='Operating Model'!F23 -> 9100 | F15: ='Operating Model'!G23 -> 0
C16: ='Operating Model'!C24 -> Закуп товарного стада | D16: тыс. тенге | E16: ='Operating Model'!F24 -> 0 | F16: ='Operating Model'!G24 -> 0
B17: Итого долгосрочные инвестиции | D17: тыс. тенге | E17: =E9+E13 -> 421565.15 | F17: =F9+F13 -> 0
B18: Оборотный капитал (первые 2 года) | D18: тыс. тенге | E18: ='Operating Model'!F26 -> 56436.079 | F18: ='Operating Model'!G26 -> 0
B19: Итого стоимость проекта | D19: тыс. тенге | E19: =SUM(E17,E18) -> 478001.22 | F19: =SUM(F17,F18) -> 0
B22: Условия по займам | E22: Большая Ферма
B23: Инвестиционный займ
B24: Сумма | D24: тыс. тенге | E24: ='Operating Model'!AL9 -> 379408.63
B25: Ставка | D25: % | E25: =Loans!E4 -> 0.05
B26: Срок | D26: лет | E26: =Loans!E5 -> 10
B28: Оборотный займ | E28: =E71 -> 2026 | F28: =F71 -> 2027 | G28: =G71 -> 2028 | H28: =H71 -> 2029 | I28: =I71 -> 2030 | J28: =J71 -> 2031 | K28: =K71 -> 2032 | L28: =L71 -> 2033 | ... O28: =O71 -> 2036
B29: Сумма | D29: тыс. тенге | E29: =E46 -> 16062.139 | F29: =F46 -> 33048.538 | G29: =G46 -> 39510.59 | H29: =H46 -> 91478.45 | I29: =I46 -> 107743.92 | J29: =J46 -> 116731.42 | K29: =K46 -> 125873.93 | L29: =L46 -> 134423.33 | ... O29: =O46 -> 0
B30: Ставка | D30: % | E30: ='Operating Model'!E305 -> 0.06
B31: Срок | D31: лет | E31: ='Operating Model'!E313 -> 2 | S31: =100/20 -> 5
A33: 3 | B33: Залоговое обеспечение
B35: Этап 1 (при финансировании)
C36: Требования программы (15% от суммы займа) | D36: тыс. тенге | E36: =E24*F36 -> 56911.295 | F36: 0.15 | G36: коэффициент покрытия
C37: Залог денег | D37: тыс. тенге | E37: ='Operating Model'!AQ10 -> 0 | F37: =E37/F61 -> 0
B39: Этап 2 (высвобождение денег и оформление твердых залогов)
C40: Наличие твердых залогов (недвижимость) | D40: тыс. тенге | E40: =E56 -> 224825.15 | F40: =E40/F61 -> 0.59256729
C41: Твердые активы в залог | D41: тыс. тенге | E41: =F61*F36 -> 56911.295
C42: Необремененные твердые залоги | D42: тыс. тенге | E42: =E40-E41 -> 167913.85
A44: 4 | B44: Формирование оборотного капитала и займы на оборотку
E45: =E28 -> 2026 | F45: =F28 -> 2027 | G45: =G28 -> 2028 | H45: =H28 -> 2029 | I45: =I28 -> 2030 | J45: =J28 -> 2031 | K45: =K28 -> 2032 | L45: =L28 -> 2033 | ... O45: =O28 -> 2036
B46: Потребность в оборотном капитале | D46: тыс. тенге | E46: ='Operating Model'!AI308 -> 16062.139 | F46: ='Operating Model'!AJ308 -> 33048.538 | G46: ='Operating Model'!AK308 -> 39510.59 | H46: ='Operating Model'!AL308 -> 91478.45 | I46: ='Operating Model'!AM308 -> 107743.92 | J46: ='Operating Model'!AN308 -> 116731.42 | K46: ='Operating Model'!AO308 -> 125873.93 | L46: ='Operating Model'!AP308 -> 134423.33 | ... O46: ='Operating Model'!AS308 -> 0
B47: Необремененные твердые залоги | D47: тыс. тенге | E47: =E42 -> 167913.85 | F47: =E47 -> 167913.85 | G47: =F47 -> 167913.85 | H47: =G47 -> 167913.85 | I47: =H47 -> 167913.85 | J47: =I47 -> 167913.85
B48: Деньги на депозите | D48: тыс. тенге | E48: =E37-H61 -> -42156.515 | F48: =E48 -> -42156.515 | G48: =F48 -> -42156.515 | H48: =G48 -> -42156.515 | I48: =H48 -> -42156.515 | J48: =I48 -> -42156.515
B49: Займы покрываются (да - 1/нет - 0) | E49: =IF(SUM(E47:E48)>E46,1,0) -> 1 | F49: =IF(SUM(F47:F48)>F46,1,0) -> 1 | G49: =IF(SUM(G47:G48)>G46,1,0) -> 1 | H49: =IF(SUM(H47:H48)>H46,1,0) -> 1 | I49: =IF(SUM(I47:I48)>I46,1,0) -> 1 | J49: =IF(SUM(J47:J48)>J46,1,0) -> 1
B50: Займы покрываются (%) | D50: % | E50: =SUM(E48+E47)/E46-1 -> 6.8294262 | F50: =SUM(F48+F47)/F46-1 -> 2.8052314 | G50: =SUM(G48+G47)/G46-1 -> 2.1828767 | H50: =SUM(H48+H47)/H46-1 -> 0.37472089 | I50: =SUM(I48+I47)/I46-1 -> 0.16718733 | J50: =SUM(J48+J47)/J46-1 -> 0.077322065
...

Sheet Input
B1: Проект Franchise Karabalyk
B3: Общие вводные данные
B4: Цена закупа 1 маточного поголовья | D4: тенге | F4: 550000
B5: Цена закупа 1 быка производителя | D5: тенге | F5: 650000
B6: Норма по количеству быков-производителей | D6: ratio | F6: =1/15 -> 0.066666667
B7: Норма на пастбища | D7: га на 1 голову | F7: 10
B8: Площадь пастбищ на 1 ферму | D8: га | F8: =F7*F42 -> 3000
B9: Переключатель (1= с субсидиями, 2 - без субсидий) | F9: 1
B10: Переключатель (1= с привлечением займов на ПОС, 2 - без без привлечения займов на ПОС) | F10: 1
B11: Переключатель (1= без переоценки биоактивов, 2 - с переоценкой активов) | F11: 1
B13: Условия финансирования
B15: Капитальные затраты
C16: Ставка вознаграждения | D16: % | F16: =Output!D190 -> 0.05
C17: Срок кредитования | D17: лет | F17: 10
C18: Срок кредитования | D18: мес. | F18: =F17*12 -> 120
C19: Льготный период | D19: лет | F19: 2
C20: Доля займа | D20: % | F20: 0.9
B22: Закуп поголовья
C23: Ставка вознаграждения | D23: % | F23: 0.05
C24: Срок кредитования | D24: лет | F24: 10
C25: Срок кредитования | D25: мес. | F25: =F24*12 -> 120
C26: Льготный период | D26: лет | F26: 2
C27: Доля займа | D27: % | F27: 0.9
B29: Оборотный капитал
C30: Ставка вознаграждения | D30: % | F30: 0.06
C31: Срок кредитования | D31: лет | F31: =F32/12 -> 1.25
C32: Срок кредитования | D32: мес. | F32: 15
C33: Льготный период | D33: мес. | F33: 15
B36: Дата старта проекта | D36: дата | F36: 46265
B37: Размер паушального взноса | D37: тыс. тенге | F37: 0
B38: Минимальный размер роялти, в год | D38: тыс. тенге | F38: 0
B39: Размер собственного участия | D39: тыс. тенге | F39: =F44 -> 63234.772
B40: Закуп маточного поголовья | D40: кол-во голов | F40: =F62 -> 200 | G40: 0
B41: Закуп быков-производителей | D41: кол-во голов | F41: =ROUNDUP(F40*$F$6,0) -> 14 | G41: =ROUNDUP(G40*$F$6,0) -> 0
B42: Мощность репродуктора | D42: кол-во голов | F42: =F63 -> 300
B43: Доля собственного участия | D43: % | F43: 0.15
B44: Размер необходимого собственного участия | D44: тыс. тенге | F44: =F56*F43 -> 63234.772
F46: 1 ый год
F47: Итого | G47: Займ АКК | H47: Собственное участие
B48: Капитальные затраты | D48: тыс. тенге | F48: =SUM(F49,F50,F51) -> 302465.15 | G48: =F48-H48 -> 257095.37 | H48: =F48*$F$43 -> 45369.772
...

Sheet Feeding Rations
A1: х | B1: РАЦИОНЫ ПИТАНИЯ / FEEDING RATIONS
B3: Суточный рацион по месяцам (сезонный паттерн)
J4: 1 | K4: =J4+1 -> 2 | L4: =K4+1 -> 3 | M4: =L4+1 -> 4 | N4: =M4+1 -> 5 | O4: =N4+1 -> 6 | P4: =O4+1 -> 7 | Q4: =P4+1 -> 8 | R4: =Q4+1 -> 9 | ... U4: =T4+1 -> 12
B5: Маточное поголовье
C6: Зеленая масса | D6: кг | J6: 0 | K6: 0 | L6: 0 | M6: 0 | N6: 32 | O6: 32 | P6: 32 | Q6: 32 | R6: 32 | S6: 32 | T6: 0 | U6: 0
C7: Концентраты | D7: кг | J7: 2.4 | K7: 2.4 | L7: 2.4 | M7: 2.4 | N7: 0 | O7: 0 | P7: 0 | Q7: 0 | R7: 0 | S7: 0 | T7: 2.4 | U7: 2.4
C8: Соль поваренная | D8: кг | J8: 0.057 | K8: 0.057 | L8: 0.057 | M8: 0.057 | N8: 0.05 | O8: 0.05 | P8: 0.05 | Q8: 0.05 | R8: 0.05 | S8: 0.05 | T8: 0.06 | U8: 0.06
C9: Сено | D9: кг | J9: 7 | K9: 7 | L9: 7 | M9: 7 | N9: 0 | O9: 0 | P9: 0 | Q9: 0 | R9: 0 | S9: 0 | T9: 9 | U9: 9
C10: Сенаж | D10: кг | J10: 9 | K10: 9 | L10: 9 | M10: 9 | N10: 0 | O10: 0 | P10: 0 | Q10: 0 | R10: 0 | S10: 0 | T10: 8 | U10: 8
C11: Силос | D11: кг | J11: 15 | K11: 15 | L11: 15 | M11: 15 | N11: 0 | O11: 0 | P11: 0 | Q11: 0 | R11: 0 | S11: 0 | T11: 10 | U11: 10
C12: Диаммонийфосфат | D12: кг | J12: 0.03 | K12: 0.03 | L12: 0.03 | M12: 0.03 | N12: 0 | O12: 0 | P12: 0 | Q12: 0 | R12: 0 | S12: 0 | T12: 0.04 | U12: 0.04
C13: Монокальцийфосфат | D13: кг | J13: 0.055 | K13: 0.055 | L13: 0.055 | M13: 0.055 | N13: 0 | O13: 0 | P13: 0 | Q13: 0 | R13: 0 | S13: 0 | T13: 0.045 | U13: 0.045
B15: Быки-производители
C16: Зеленая масса | D16: кг | J16: 0 | K16: 0 | L16: 0 | M16: 0 | N16: 12 | O16: 12 | P16: 12 | Q16: 12 | R16: 12 | S16: 12 | T16: 0 | U16: 0
C17: Сено | D17: кг | J17: 4.5 | K17: 4.5 | L17: 4.5 | M17: 4.5 | N17: 0 | O17: 0 | P17: 0 | Q17: 0 | R17: 0 | S17: 0 | T17: 4.5 | U17: 4.5
C18: Силос | D18: кг | J18: 3 | K18: 3 | L18: 3 | M18: 3 | N18: 0 | O18: 0 | P18: 0 | Q18: 0 | R18: 0 | S18: 0 | T18: 3 | U18: 3
C19: Концентраты | D19: кг | J19: =3.5-0.72 -> 2.78 | K19: =3.5-0.72 -> 2.78 | L19: =3.5-0.72 -> 2.78 | M19: =3.5-0.72 -> 2.78 | N19: 0 | O19: 0 | P19: 0 | Q19: 0 | R19: 0 | S19: 0 | T19: =3.5-0.72 -> 2.78 | U19: =3.5-0.72 -> 2.78
C20: БМВД | D20: кг | J20: 0.72 | K20: 0.72 | L20: 0.72 | M20: 0.72 | N20: 0 | O20: 0 | P20: 0 | Q20: 0 | R20: 0 | S20: 0 | T20: 0.72 | U20: 0.72
C21: Соль поваренная | D21: кг | J21: 0.045 | K21: 0.045 | L21: 0.045 | M21: 0.045 | N21: 0.05 | O21: 0.05 | P21: 0.05 | Q21: 0.05 | R21: 0.05 | S21: 0.05 | T21: 0.045 | U21: 0.045
B23: Молодняк
C24: Молоко | D24: л | J24: 7 | K24: 6 | L24: 5 | M24: 4 | N24: 4 | O24: 5 | P24: 0 | Q24: 0 | R24: 0 | S24: 0 | T24: 0 | U24: 6
C25: Сено | D25: кг | J25: 0.3 | K25: 0.5 | L25: 1 | M25: 1.2 | N25: 0 | O25: 0 | P25: 0 | Q25: 0 | R25: 0 | S25: 0 | T25: 0 | U25: 0
C26: Силос | D26: кг | J26: 0 | K26: 2 | L26: 4 | M26: 4 | N26: 0 | O26: 0 | P26: 0 | Q26: 0 | R26: 0 | S26: 0 | T26: 0 | U26: 0
C27: Концентраты | D27: кг | J27: 0.2 | K27: 0.4 | L27: 0.6 | M27: 0.7 | N27: 0 | O27: 0 | P27: 0 | Q27: 0 | R27: 0 | S27: 0 | T27: 0 | U27: 0
C28: Соль поваренная | D28: кг | J28: 0.008 | K28: 0.012 | L28: 0.016 | M28: 0.018 | N28: 0.022 | O28: 0.027 | P28: 0 | Q28: 0 | R28: 0 | S28: 0 | T28: 0 | U28: 0
C29: Кормовой фосфат | D29: кг | J29: 0.01 | K29: 0.02 | L29: 0.03 | M29: 0.03 | N29: 0.04 | O29: 0.03 | P29: 0 | Q29: 0 | R29: 0 | S29: 0 | T29: 0 | U29: 0
C30: Зеленая масса | D30: кг | J30: 0 | K30: 0 | L30: 0 | M30: 0 | N30: 0 | O30: 9 | P30: 0 | Q30: 0 | R30: 0 | S30: 0 | T30: 0 | U30: 0
B32: Телочки
C33: Зеленая масса | D33: кг | J33: 0 | K33: 0 | L33: 0 | M33: 0 | N33: 29 | O33: 29 | P33: 29 | Q33: 29 | R33: 29 | S33: 29 | T33: 0 | U33: 0
C34: Концентраты | D34: кг | J34: 0 | K34: 0 | L34: 0 | M34: 0 | N34: 0 | O34: 0 | P34: 0 | Q34: 0 | R34: 0 | S34: 0 | T34: 0 | U34: 0
C35: Соль поваренная | D35: кг | J35: 0.03 | K35: 0.03 | L35: 0.03 | M35: 0.03 | N35: 0.03 | O35: 0.03 | P35: 0.03 | Q35: 0.03 | R35: 0.03 | S35: 0.03 | T35: 0.03 | U35: 0.03
C36: Кормовой фосфат | D36: кг | J36: 0.03 | K36: 0.03 | L36: 0.03 | M36: 0.03 | N36: 0.03 | O36: 0.03 | P36: 0.03 | Q36: 0.03 | R36: 0.03 | S36: 0.03 | T36: 0.03 | U36: 0.03
C37: Сено | D37: кг | J37: 4 | K37: 4 | L37: 4 | M37: 4 | N37: 0 | O37: 0 | P37: 0 | Q37: 0 | R37: 0 | S37: 0 | T37: 4 | U37: 4
C38: Сенаж | D38: кг | J38: 5 | K38: 5 | L38: 5 | M38: 5 | N38: 0 | O38: 0 | P38: 0 | Q38: 0 | R38: 0 | S38: 0 | T38: 5 | U38: 5
C39: Дерть ячменная | D39: кг | J39: 0.3 | K39: 0.3 | L39: 0.3 | M39: 0.3 | N39: 0 | O39: 0 | P39: 0 | Q39: 0 | R39: 0 | S39: 0 | T39: 0.3 | U39: 0.3
C40: Зерноотходы | D40: кг | J40: 1.6 | K40: 1.6 | L40: 1.6 | M40: 1.6 | N40: 0 | O40: 0 | P40: 0 | Q40: 0 | R40: 0 | S40: 0 | T40: 1.6 | U40: 1.6
B42: Бычки
C43: Зеленая масса | D43: кг | J43: 0 | K43: 0 | L43: 0 | M43: 0 | N43: 30 | O43: 30 | P43: 30 | Q43: 30 | R43: 30 | S43: 30 | T43: 0 | U43: 0
C44: Концентраты | D44: кг | J44: 0 | K44: 0 | L44: 0 | M44: 0 | N44: 0 | O44: 0 | P44: 0 | Q44: 0 | R44: 0 | S44: 0 | T44: 0 | U44: 0
C45: Соль поваренная | D45: кг | J45: 0 | K45: 0 | L45: 0 | M45: 0 | N45: 0.04 | O45: 0.04 | P45: 0.04 | Q45: 0.04 | R45: 0.04 | S45: 0.04 | T45: 0 | U45: 0
...

Sheet Operating Model
B1: Проект Model Farm Zhailau
C2: Модель консорциума, без управляющей компании | AI2: 46387 | AJ2: =EOMONTH(AI2,12) -> 46752 | AK2: =EOMONTH(AJ2,12) -> 47118 | AL2: =EOMONTH(AK2,12) -> 47483 | AM2: =EOMONTH(AL2,12) -> 47848 | AN2: =EOMONTH(AM2,12) -> 48213 | AO2: =EOMONTH(AN2,12) -> 48579 | AP2: =EOMONTH(AO2,12) -> 48944 | AQ2: =EOMONTH(AP2,12) -> 49309 | ... AT2: =EOMONTH(AS2,12) -> 50405 | AU2: https://adilet.zan.kz/rus/docs/V2500036215#z85
A3: х | B3: Саммари проекта
AN4: Темп роста для модели Гордона | AQ4: 0.03
B5: Дата старта проекта | F5: 46265
B6: Стартовый взнос инвестора | F6: =Input!F39 -> 63234.772
B7: Кол-во хозяйств | D7: ед. | F7: 1 | AI7: Источники финансирования проекта
B8: Цена 1 маточного поголовья | D8: тенге | F8: 550000 | AK8: % | AL8: Сумма, тыс. тенге | AM8: Сумма, тыс. тенге | AN8: Сумма, тыс. тенге
B9: Цена 1 быка производителя | D9: тенге | F9: 750000 | AI9: Займ | AK9: 0.9 | AL9: =AL12*AK9 -> 379408.63 | AM9: =AM12*AK9 -> 0 | AN9: =SUM(AL9:AM9) -> 379408.63
B10: Переключатель (1= с субсидиями, 2 - без субсидий) | F10: 1 | AI10: Первоначальный взнос | AK10: 0.1 | AL10: =AK10*AL12 -> 42156.515 | AM10: =AM12*AK10 -> 0 | AN10: =SUM(AL10:AM10) -> 42156.515
B11: Переключатель (1= с привлечением займов на ПОС, 2 - без без привлечения займов на ПОС) | F11: 1 | AI11: Старт взнос | AK11: 0 | AL11: =F6-AL10 -> 21078.257 | AM11: 0 | AN11: =SUM(AL11:AM11) -> 21078.257
B12: Переключатель (1= без переоценки биоактивов, 2 - с переоценкой активов) | F12: 1 | AI12: Итого | AK12: =SUM(AK9:AK11) -> 1 | AL12: =F16 -> 421565.15 | AM12: =G16 -> 0 | AN12: =SUM(AL12:AM12) -> 421565.15
B16: Капитальные затраты, итого | F16: =SUM(F17:F24) -> 421565.15 | AI16: Ключевые показатели проекта
C17: Предварительные расходы | D17: тыс. тенге | F17: =Input!F49 -> 20000
C18: Строительство зданий и инфраструктура | D18: тыс. тенге | F18: =Input!F50 -> 224825.15 | AL18: =D414 -> Без учета остатка КРС
C19: Спецтехника и оборудование | D19: тыс. тенге | F19: =Input!F51 -> 57640 | AI19: =C415 -> NPV (10 лет) | AL19: =D415 -> 458767.09
C21: Финансирование административных затрат (первые 3 лет) | D21: тыс. тенге | F21: 0
C22: Маточное поголовье | D22: тыс. тенге | F22: =Input!F53 -> 110000 | AI22: =C416 -> IRR (10 лет) | AL22: =D416 -> 0.17060885
C23: Быки-проивзодители | D23: тыс. тенге | F23: =Input!F54 -> 9100 | AI23: =C417 -> Простая окупаемость | AL23: =D417 -> 7.2195121
C24: Закуп товарного стада | D24: тыс. тенге | F24: 0 | AI24: =C418 -> Дисконтированная окупаемость | AL24: =D418 -> 8.150759
B26: Оборотный капитал, итого | D26: тыс. тенге | F26: =SUM(J308:AG308) -> 56436.079
A28: х | B28: Макроэкономические показатели
J29: =EOMONTH(F5,0) -> 46265 | K29: =EOMONTH(J29,1) -> 46295 | L29: =EOMONTH(K29,1) -> 46326 | M29: =EOMONTH(L29,1) -> 46356 | N29: =EOMONTH(M29,1) -> 46387 | O29: =EOMONTH(N29,1) -> 46418 | P29: =EOMONTH(O29,1) -> 46446 | Q29: =EOMONTH(P29,1) -> 46477 | R29: =EOMONTH(Q29,1) -> 46507 | ... AG29: =EOMONTH(AF29,1) -> 46965 | AI29: =AI38 -> 2026 | AJ29: =AJ38 -> 2027 | AK29: =AK38 -> 2028 | AL29: =AL38 -> 2029 | AM29: =AM38 -> 2030 | AN29: =AN38 -> 2031 | AO29: =AO38 -> 2032 | AP29: =AP38 -> 2033 | ... AT29: =AT38 -> 2037
B30: Рост ВВП | D30: % | E30: https://www.imf.org/external/datamapper/profile/KAZ | F30: IMF | AI30: 4.3 | AJ30: 3.8 | AK30: 2.6 | AL30: 3.1 | AM30: 3.1 | AN30: 3.1 | AO30: 3.1 | AP30: 3.1 | AQ30: 3.1 | AR30: 3.1 | AS30: 3.1 | AT30: 3.1
B31: ИПЦ в KZ, ср. | D31: % | E31: https://www.imf.org/external/datamapper/profile/KAZ | F31: IMF | J31: 1 | K31: =J31 -> 1 | L31: =K31 -> 1 | M31: =L31 -> 1 | N31: =M31 -> 1 | O31: =AJ31+N31 -> 1.105 | P31: 1 | Q31: 1 | R31: 1 | S31: 1 | T31: 1 | U31: 1 | V31: 1 | W31: 1 | X31: 1 | Y31: 1 | Z31: 1 | AA31: =AK31+Z31 -> 1.1 | AB31: 1 | AC31: 1 | AD31: 1 | AE31: 1 | AF31: 1 | AG31: 1 | AI31: 0.11 | AJ31: 0.105 | AK31: 0.1 | AL31: 0.095 | AM31: 0.09 | AN31: 0.085 | AO31: 0.08 | AP31: 0.07 | AQ31: 0.065 | AR31: 0.06 | AS31: 0.05 | AT31: 0.05
B32: KZT/USD | D32: тенге/долл. США | AI32: 550 | AJ32: =AI32*(1+5%) -> 577.5 | AK32: =AJ32*(1+5%) -> 606.375 | AL32: =AK32*(1+5%) -> 636.69375 | AM32: =AL32*(1+5%) -> 668.52844 | AN32: =AM32*(1+5%) -> 701.95486 | AO32: =AN32*(1+5%) -> 737.0526 | AP32: =AO32*(1+5%) -> 773.90523 | AQ32: =AP32*(1+5%) -> 812.60049 | ... AT32: =AS32*(1+5%) -> 940.68665
A34: х | B34: Движение скота
J35: 1 | K35: =J35+1 -> 2 | L35: =K35+1 -> 3 | M35: =L35+1 -> 4 | N35: =M35+1 -> 5 | O35: =N35+1 -> 6 | P35: =O35+1 -> 7 | Q35: =P35+1 -> 8 | R35: =Q35+1 -> 9 | ... AG35: =AF35+1 -> 24 | AI35: 5 | AJ35: 12 | AK35: 12 | AL35: 12 | AM35: 12 | AN35: 12 | AO35: 12 | AP35: 12 | AQ35: 12 | AR35: 12 | AS35: 12 | AT35: 12
A36: Репродуктор
J37: =YEAR(J39) -> 2026 | K37: =YEAR(K39) -> 2026 | L37: =YEAR(L39) -> 2026 | M37: =YEAR(M39) -> 2026 | N37: =YEAR(N39) -> 2026 | O37: =YEAR(O39) -> 2027 | P37: =YEAR(P39) -> 2027 | Q37: =YEAR(Q39) -> 2027 | ... AG37: =YEAR(AG39) -> 2028 | AI37: =YEAR(AI39) -> 2026 | AJ37: =YEAR(AJ39) -> 2027 | AK37: =YEAR(AK39) -> 2028 | AL37: =YEAR(AL39) -> 2029 | AM37: =YEAR(AM39) -> 2030 | AN37: =YEAR(AN39) -> 2031 | AO37: =YEAR(AO39) -> 2032 | AP37: =YEAR(AP39) -> 2033 | ... AT37: =YEAR(AT39) -> 2037
E38: Год | G38: Месяц | J38: 46265 | K38: =EDATE(J38,1) -> 46295 | L38: =EDATE(K38,1) -> 46325 | M38: =EDATE(L38,1) -> 46356 | N38: =EDATE(M38,1) -> 46386 | O38: =EDATE(N38,1) -> 46417 | P38: =EDATE(O38,1) -> 46446 | Q38: =EDATE(P38,1) -> 46474 | R38: =EDATE(Q38,1) -> 46505 | ... AG38: =EDATE(AF38,1) -> 46962 | AI38: =YEAR(AI2) -> 2026 | AJ38: =YEAR(AJ2) -> 2027 | AK38: =YEAR(AK2) -> 2028 | AL38: =YEAR(AL2) -> 2029 | AM38: =YEAR(AM2) -> 2030 | AN38: =YEAR(AN2) -> 2031 | AO38: =YEAR(AO2) -> 2032 | AP38: =YEAR(AP2) -> 2033 | ... AT38: =YEAR(AT2) -> 2037
J39: 46265 | K39: =EOMONTH(J39,1) -> 46295 | L39: =EOMONTH(K39,1) -> 46326 | M39: =EOMONTH(L39,1) -> 46356 | N39: =EOMONTH(M39,1) -> 46387 | O39: =EOMONTH(N39,1) -> 46418 | P39: =EOMONTH(O39,1) -> 46446 | Q39: =EOMONTH(P39,1) -> 46477 | R39: =EOMONTH(Q39,1) -> 46507 | ... AG39: =EOMONTH(AF39,1) -> 46965 | AI39: 46387 | AJ39: =EOMONTH(AI39,12) -> 46752 | AK39: =EOMONTH(AJ39,12) -> 47118 | AL39: =EOMONTH(AK39,12) -> 47483 | AM39: =EOMONTH(AL39,12) -> 47848 | AN39: =EOMONTH(AM39,12) -> 48213 | AO39: =EOMONTH(AN39,12) -> 48579 | AP39: =EOMONTH(AO39,12) -> 48944 | AQ39: =EOMONTH(AP39,12) -> 49309 | ... AT39: =EOMONTH(AS39,12) -> 50405
B41: Мощность репродуктора | D41: голов | E41: =Input!F42 -> 300 | J41: =$E$41*J42 -> 300 | K41: =$E$41*K42 -> 300 | L41: =$E$41*L42 -> 300 | M41: =$E$41*M42 -> 300 | N41: =$E$41*N42 -> 300 | O41: =$E$41*O42 -> 300 | P41: =$E$41*P42 -> 300 | Q41: =$E$41*Q42 -> 300 | ... AG41: =$E$41*AG42 -> 300 | AI41: =$E$41*AI42 -> 300 | AJ41: =$E$41*AJ42 -> 300 | AK41: =$E$41*AK42 -> 300 | AL41: =$E$41*AL42 -> 300 | AM41: =$E$41*AM42 -> 300 | AN41: =$E$41*AN42 -> 300 | AO41: =$E$41*AO42 -> 300 | AP41: =$E$41*AP42 -> 300 | ... AT41: =$E$41*AT42 -> 300
B42: Кол-во репродукторов | D42: ед. | J42: =J45 -> 1 | K42: =J42 -> 1 | L42: =K42 -> 1 | M42: =L42 -> 1 | N42: =M42 -> 1 | O42: =N42 -> 1 | P42: =O42 -> 1 | Q42: =P42 -> 1 | R42: =Q42 -> 1 | ... AG42: =AF42 -> 1 | AI42: 1 | AJ42: =AI42 -> 1 | AK42: =AJ42 -> 1 | AL42: =AK42 -> 1 | AM42: =AL42 -> 1 | AN42: =AM42 -> 1 | AO42: =AN42 -> 1 | AP42: =AO42 -> 1 | AQ42: =AP42 -> 1 | ... AT42: =AS42 -> 1
B45: Количество хозяйств | D45: единиц | J45: 1 | K45: 0 | L45: 0 | M45: 0 | N45: 0 | O45: 0 | P45: 0 | Q45: 0 | R45: 0 | S45: =J45 -> 1 | T45: 0 | U45: 0 | V45: 0 | W45: 0 | X45: 0 | Y45: 0 | Z45: 0 | AA45: 0 | AB45: 0 | AC45: 0 | AD45: 0 | AE45: 0 | AF45: 0 | AG45: 0 | AI45: =F7 -> 1 | AJ45: 0 | AK45: 0 | AL45: 0 | AM45: 0 | AN45: 0 | AO45: 0 | AP45: 0 | AQ45: 0 | AR45: 0 | AS45: 0 | AT45: 0
B46: Закуп маточного поголовья | D46: голов | E46: =Input!F40 -> 200 | J46: =$E$46*J45 -> 200 | K46: 0 | L46: 0 | M46: 0 | N46: 0 | O46: 0 | P46: 0 | Q46: 0 | R46: 0 | S46: =$F$46*S45 -> 0 | T46: 0 | U46: 0 | V46: 0 | W46: 0 | X46: 0 | Y46: 0 | Z46: 0 | AA46: 0 | AB46: 0 | AC46: 0 | AD46: 0 | AE46: 0 | AF46: 0 | AG46: 0 | AI46: =SUMIF($J$37:$AG$37,AI$37,$J46:$AG46) -> 200 | AJ46: =SUMIF($J$37:$AG$37,AJ$37,$J46:$AG46) -> 0 | AK46: 0 | AL46: =SUMIF($J$37:$AG$37,AL$37,$J46:$AG46) -> 0 | AM46: 0 | AN46: 0 | AO46: 0 | AP46: 0 | AQ46: 0 | AR46: 0 | AS46: 0 | AT46: 0
B47: Закуп быков производителей | D47: голов | E47: =ROUNDUP(E48,0) -> 14 | J47: =$E$47*J45 -> 14 | K47: 0 | L47: 0 | M47: 0 | N47: 0 | O47: 0 | P47: 0 | Q47: 0 | R47: 0 | S47: =F47 -> 0 | T47: 0 | U47: 0 | V47: 0 | W47: 0 | X47: 0 | Y47: 0 | Z47: 0 | AA47: 0 | AB47: 0 | AC47: 0 | AD47: 0 | AE47: 0 | AF47: 0 | AG47: 0 | AI47: =SUMIF($J$37:$AG$37,AI$37,$J47:$AG47) -> 14 | AJ47: =SUMIF($J$37:$AG$37,AJ$37,$J47:$AG47) -> 0 | AK47: 0 | AL47: =SUMIF($J$37:$AG$37,AL$37,$J47:$AG47) -> 0 | AM47: 0 | AN47: 0 | AO47: 0 | AP47: 0 | AQ47: 0 | AR47: 0 | AS47: 0 | AT47: 0
B48: Норма для быков производителей | D48: коэф-т | E48: =1/15*E46 -> 13.333333
B50: Маточное поголовье н.п. | D50: голов | J50: 0 | K50: =J57 -> 200 | L50: =K57 -> 199.5 | M50: =L57 -> 199.00125 | N50: =M57 -> 198.50375 | O50: =N57 -> 198.00749 | P50: =O57 -> 197.51247 | Q50: =P57 -> 197.01869 | R50: =Q57 -> 196.52614 | ... AG50: =AF57 -> 160.82024 | AI50: 0 | AJ50: =AI57 -> 198.00749 | AK50: =AJ57 -> 163.25379 | AL50: =AK57 -> 201.16948 | AM50: =AL57 -> 247.89109 | AN50: =AM57 -> 300 | AO50: =AN57 -> 300 | AP50: =AO57 -> 300 | AQ50: =AP57 -> 300 | ... AT50: =AS57 -> 300
B51: + | C51: Покупка маточного поголовья | D51: голов | J51: =J46 -> 200 | K51: =K46 -> 0 | L51: =L46 -> 0 | M51: =M46 -> 0 | N51: =N46 -> 0 | O51: =O46 -> 0 | P51: =P46 -> 0 | Q51: =Q46 -> 0 | ... AG51: =AG46 -> 0 | AI51: =SUMIF($J$37:$AG$37,AI$37,$J51:$AG51) -> 200 | AJ51: =SUMIF($J$37:$AG$37,AJ$37,$J51:$AG51) -> 0 | AK51: =AK46 -> 0 | AL51: =AL46 -> 0 | AM51: =AM46 -> 0 | AN51: =AN46 -> 0 | AO51: =AO46 -> 0 | AP51: =AP46 -> 0 | AQ51: =AQ46 -> 0 | AR51: =AR46 -> 0 | ... AT51: =AT46 -> 0
...

Sheet Cattle Feeding Cycle
C1: 46235
A3: х | B3: Рационы питания
B4: Кол-во дней в месяце | J4: =J5-C1 -> 30 | K4: =K5-J5 -> 30 | L4: =L5-K5 -> 31 | M4: =M5-L5 -> 30 | N4: =N5-M5 -> 31 | O4: =O5-N5 -> 31 | P4: =P5-O5 -> 28 | Q4: =Q5-P5 -> 31 | R4: =R5-Q5 -> 30 | ... AG4: =AG5-AF5 -> 31 | AI4: =SUM(J4:N4) -> 152 | AJ4: =DATE(AJ5,12,31)-DATE(AI5,12,31) -> 365 | AK4: =DATE(AK5,12,31)-DATE(AJ5,12,31) -> 366 | AL4: =DATE(AL5,12,31)-DATE(AK5,12,31) -> 365 | AM4: =DATE(AM5,12,31)-DATE(AL5,12,31) -> 365 | AN4: =DATE(AN5,12,31)-DATE(AM5,12,31) -> 365 | AO4: =DATE(AO5,12,31)-DATE(AN5,12,31) -> 366 | AP4: =DATE(AP5,12,31)-DATE(AO5,12,31) -> 365 | AQ4: =DATE(AQ5,12,31)-DATE(AP5,12,31) -> 365 | ... AT4: =DATE(AT5,12,31)-DATE(AS5,12,31) -> 365
B5: Типовой суточный рацион питания на 1 КРС | J5: 46265 | K5: =EOMONTH(J5,1) -> 46295 | L5: =EOMONTH(K5,1) -> 46326 | M5: =EOMONTH(L5,1) -> 46356 | N5: =EOMONTH(M5,1) -> 46387 | O5: =EOMONTH(N5,1) -> 46418 | P5: =EOMONTH(O5,1) -> 46446 | Q5: =EOMONTH(P5,1) -> 46477 | R5: =EOMONTH(Q5,1) -> 46507 | ... AG5: =EOMONTH(AF5,1) -> 46965 | AI5: =AI146 -> 2026 | AJ5: =AJ146 -> 2027 | AK5: =AK146 -> 2028 | AL5: =AL146 -> 2029 | AM5: =AM146 -> 2030 | AN5: =AN146 -> 2031 | AO5: =AO146 -> 2032 | AP5: =AP146 -> 2033 | ... AT5: =AT146 -> 2037
B7: Маточное поголовье полный год
C8: Зеленая масса | D8: кг | J8: 32 | K8: 32 | L8: 32 | M8: 0 | N8: 0 | O8: 0 | P8: 0 | Q8: 0 | R8: 0 | S8: 32 | T8: 32 | U8: 32 | V8: 32 | W8: 32 | X8: 32 | Y8: 0 | Z8: 0 | AA8: 0 | AB8: 0 | AC8: 0 | AD8: 0 | AE8: 32 | AF8: 32 | AG8: 32 | AI8: =SUMPRODUCT(J8:N8,J$4:N$4) -> 2912 | AJ8: =SUMPRODUCT(O8:Z8,O$4:Z$4) -> 5888 | AK8: =AJ8 -> 5888 | AL8: =AK8 -> 5888 | AM8: =AL8 -> 5888 | AN8: =AM8 -> 5888 | AO8: =AN8 -> 5888 | AP8: =AO8 -> 5888 | AQ8: =AP8 -> 5888 | AR8: =AQ8 -> 5888 | ... AT8: =AS8 -> 5888
C9: Концентраты | D9: кг | J9: 0 | K9: 0 | L9: 0 | M9: 2 | N9: 2 | O9: 2 | P9: 2 | Q9: 2 | R9: 2 | S9: 0 | T9: 0 | U9: 0 | V9: 0 | W9: 0 | X9: 0 | Y9: 2 | Z9: 2 | AA9: 2 | AB9: 2 | AC9: 2 | AD9: 2 | AE9: 0 | AF9: 0 | AG9: 0 | AI9: =SUMPRODUCT(J9:N9,J$4:N$4) -> 122 | AJ9: =SUMPRODUCT(O9:Z9,O$4:Z$4) -> 362 | AK9: =AJ9 -> 362 | AL9: =AK9 -> 362 | AM9: =AL9 -> 362 | AN9: =AM9 -> 362 | AO9: =AN9 -> 362 | AP9: =AO9 -> 362 | AQ9: =AP9 -> 362 | AR9: =AQ9 -> 362 | ... AT9: =AS9 -> 362
C10: Соль поваренная | D10: кг | J10: 0.05 | K10: 0.05 | L10: 0.05 | M10: 0.06 | N10: 0.06 | O10: 0.057 | P10: 0.057 | Q10: 0.057 | R10: 0.057 | S10: 0.05 | T10: 0.05 | U10: 0.05 | V10: 0.05 | W10: 0.05 | X10: 0.05 | Y10: 0.06 | Z10: 0.06 | AA10: 0.057 | AB10: 0.057 | AC10: 0.057 | AD10: 0.057 | AE10: 0.05 | AF10: 0.05 | AG10: 0.05 | AI10: =SUMPRODUCT(J10:N10,J$4:N$4) -> 8.21 | AJ10: =SUMPRODUCT(O10:Z10,O$4:Z$4) -> 19.7 | AK10: =AJ10 -> 19.7 | AL10: =AK10 -> 19.7 | AM10: =AL10 -> 19.7 | AN10: =AM10 -> 19.7 | AO10: =AN10 -> 19.7 | AP10: =AO10 -> 19.7 | AQ10: =AP10 -> 19.7 | AR10: =AQ10 -> 19.7 | ... AT10: =AS10 -> 19.7
C11: Сено | D11: кг | J11: 0 | K11: 0 | L11: 0 | M11: 8 | N11: 8 | O11: 6 | P11: 6 | Q11: 6 | R11: 6 | S11: 0 | T11: 0 | U11: 0 | V11: 0 | W11: 0 | X11: 0 | Y11: 8 | Z11: 8 | AA11: 6 | AB11: 6 | AC11: 6 | AD11: 6 | AE11: 0 | AF11: 0 | AG11: 0 | AI11: =SUMPRODUCT(J11:N11,J$4:N$4) -> 488 | AJ11: =SUMPRODUCT(O11:Z11,O$4:Z$4) -> 1208 | AK11: =AJ11 -> 1208 | AL11: =AK11 -> 1208 | AM11: =AL11 -> 1208 | AN11: =AM11 -> 1208 | AO11: =AN11 -> 1208 | AP11: =AO11 -> 1208 | AQ11: =AP11 -> 1208 | AR11: =AQ11 -> 1208 | ... AT11: =AS11 -> 1208
C12: Солома | D12: кг | J12: 0 | K12: 0 | L12: 0 | M12: 2 | N12: 2 | O12: 2 | P12: 2 | Q12: 2 | R12: 2 | S12: 0 | T12: 0 | U12: 0 | V12: 0 | W12: 0 | X12: 0 | Y12: 2 | Z12: 2 | AA12: 2 | AB12: 2 | AC12: 2 | AD12: 2 | AE12: 0 | AF12: 0 | AG12: 0 | AI12: =SUMPRODUCT(J12:N12,J$4:N$4) -> 122 | AJ12: =SUMPRODUCT(O12:Z12,O$4:Z$4) -> 362 | AK12: =AJ12 -> 362 | AL12: =AK12 -> 362 | AM12: =AL12 -> 362 | AN12: =AM12 -> 362 | AO12: =AN12 -> 362 | AP12: =AO12 -> 362 | AQ12: =AP12 -> 362 | AR12: =AQ12 -> 362 | ... AT12: =AS12 -> 362
C13: Отруби/шрот | D13: кг | J13: 0 | K13: 0 | L13: 0 | M13: 1 | N13: 1 | O13: 1 | P13: 1 | Q13: 1 | R13: 1 | S13: 0 | T13: 0 | U13: 0 | V13: 0 | W13: 0 | X13: 0 | Y13: 1 | Z13: 1 | AA13: 1 | AB13: 1 | AC13: 1 | AD13: 1 | AE13: 0 | AF13: 0 | AG13: 0 | AI13: =SUMPRODUCT(J13:N13,J$4:N$4) -> 61 | AJ13: =SUMPRODUCT(O13:Z13,O$4:Z$4) -> 181 | AK13: =AJ13 -> 181 | AL13: =AK13 -> 181 | AM13: =AL13 -> 181 | AN13: =AM13 -> 181 | AO13: =AN13 -> 181 | AP13: =AO13 -> 181 | AQ13: =AP13 -> 181 | AR13: =AQ13 -> 181 | ... AT13: =AS13 -> 181
C14: Диаммонийфосфат (премикс) | D14: кг | J14: 0 | K14: 0 | L14: 0 | M14: 0.04 | N14: 0.04 | O14: 0.03 | P14: 0.03 | Q14: 0.03 | R14: 0.03 | S14: 0 | T14: 0 | U14: 0 | V14: 0 | W14: 0 | X14: 0 | Y14: 0.04 | Z14: 0.04 | AA14: 0.03 | AB14: 0.03 | AC14: 0.03 | AD14: 0.03 | AE14: 0 | AF14: 0 | AG14: 0 | AI14: =SUMPRODUCT(J14:N14,J$4:N$4) -> 2.44 | AJ14: =SUMPRODUCT(O14:Z14,O$4:Z$4) -> 6.04 | AK14: =AJ14 -> 6.04 | AL14: =AK14 -> 6.04 | AM14: =AL14 -> 6.04 | AN14: =AM14 -> 6.04 | AO14: =AN14 -> 6.04 | AP14: =AO14 -> 6.04 | AQ14: =AP14 -> 6.04 | AR14: =AQ14 -> 6.04 | ... AT14: =AS14 -> 6.04
C15: Монокальцийфосфат (премикс) | D15: кг | J15: 0 | K15: 0 | L15: 0 | M15: 0.045 | N15: 0.045 | O15: 0.055 | P15: 0.055 | Q15: 0.055 | R15: 0.055 | S15: 0 | T15: 0 | U15: 0 | V15: 0 | W15: 0 | X15: 0 | Y15: 0.045 | Z15: 0.045 | AA15: 0.055 | AB15: 0.055 | AC15: 0.055 | AD15: 0.055 | AE15: 0 | AF15: 0 | AG15: 0 | AI15: =SUMPRODUCT(J15:N15,J$4:N$4) -> 2.745 | AJ15: =SUMPRODUCT(O15:Z15,O$4:Z$4) -> 9.345 | AK15: =AJ15 -> 9.345 | AL15: =AK15 -> 9.345 | AM15: =AL15 -> 9.345 | AN15: =AM15 -> 9.345 | AO15: =AN15 -> 9.345 | AP15: =AO15 -> 9.345 | AQ15: =AP15 -> 9.345 | AR15: =AQ15 -> 9.345 | ... AT15: =AS15 -> 9.345
B17: Маточное поголовье 9 мес.
C18: Зеленая масса | D18: кг | R18: 0 | S18: 32 | T18: 32 | U18: 32 | V18: 32 | W18: 32 | X18: 32 | Y18: 0 | Z18: 0 | AA18: 0 | AB18: 0 | AC18: 0 | AD18: 0 | AE18: 32 | AF18: 32 | AG18: 32 | AI18: =SUMPRODUCT(J18:N18,J$4:N$4) -> 0 | AJ18: =SUMPRODUCT(O18:Z18,O$4:Z$4) -> 5888 | AK18: =AJ18 -> 5888 | AL18: =AK18 -> 5888 | AM18: =AL18 -> 5888 | AN18: =AM18 -> 5888 | AO18: =AN18 -> 5888 | AP18: =AO18 -> 5888 | AQ18: =AP18 -> 5888 | AR18: =AQ18 -> 5888 | ... AT18: =AS18 -> 5888
C19: Концентраты | D19: кг | R19: 2 | S19: 0 | T19: 0 | U19: 0 | V19: 0 | W19: 0 | X19: 0 | Y19: 2 | Z19: 2 | AA19: 2 | AB19: 2 | AC19: 2 | AD19: 2 | AE19: 0 | AF19: 0 | AG19: 0 | AI19: =SUMPRODUCT(J19:N19,J$4:N$4) -> 0 | AJ19: =SUMPRODUCT(O19:Z19,O$4:Z$4) -> 182 | AK19: =AJ19 -> 182 | AL19: =AK19 -> 182 | AM19: =AL19 -> 182 | AN19: =AM19 -> 182 | AO19: =AN19 -> 182 | AP19: =AO19 -> 182 | AQ19: =AP19 -> 182 | AR19: =AQ19 -> 182 | ... AT19: =AS19 -> 182
C20: Соль поваренная | D20: кг | R20: 0.057 | S20: 0.05 | T20: 0.05 | U20: 0.05 | V20: 0.05 | W20: 0.05 | X20: 0.05 | Y20: 0.06 | Z20: 0.06 | AA20: 0.057 | AB20: 0.057 | AC20: 0.057 | AD20: 0.057 | AE20: 0.05 | AF20: 0.05 | AG20: 0.05 | AI20: =SUMPRODUCT(J20:N20,J$4:N$4) -> 0 | AJ20: =SUMPRODUCT(O20:Z20,O$4:Z$4) -> 14.57 | AK20: =AJ20 -> 14.57 | AL20: =AK20 -> 14.57 | AM20: =AL20 -> 14.57 | AN20: =AM20 -> 14.57 | AO20: =AN20 -> 14.57 | AP20: =AO20 -> 14.57 | AQ20: =AP20 -> 14.57 | AR20: =AQ20 -> 14.57 | ... AT20: =AS20 -> 14.57
C21: Сено | D21: кг | R21: 7 | S21: 0 | T21: 0 | U21: 0 | V21: 0 | W21: 0 | X21: 0 | Y21: 8 | Z21: 8 | AA21: 7 | AB21: 7 | AC21: 7 | AD21: 7 | AE21: 0 | AF21: 0 | AG21: 0 | AI21: =SUMPRODUCT(J21:N21,J$4:N$4) -> 0 | AJ21: =SUMPRODUCT(O21:Z21,O$4:Z$4) -> 698 | AK21: =AJ21 -> 698 | AL21: =AK21 -> 698 | AM21: =AL21 -> 698 | AN21: =AM21 -> 698 | AO21: =AN21 -> 698 | AP21: =AO21 -> 698 | AQ21: =AP21 -> 698 | AR21: =AQ21 -> 698 | ... AT21: =AS21 -> 698
C22: Солома | D22: кг | R22: 2 | S22: 0 | T22: 0 | U22: 0 | V22: 0 | W22: 0 | X22: 0 | Y22: 2 | Z22: 2 | AA22: 2 | AB22: 2 | AC22: 2 | AD22: 2 | AE22: 0 | AF22: 0 | AG22: 0 | AI22: =SUMPRODUCT(J22:N22,J$4:N$4) -> 0 | AJ22: =SUMPRODUCT(O22:Z22,O$4:Z$4) -> 182 | AK22: =AJ22 -> 182 | AL22: =AK22 -> 182 | AM22: =AL22 -> 182 | AN22: =AM22 -> 182 | AO22: =AN22 -> 182 | AP22: =AO22 -> 182 | AQ22: =AP22 -> 182 | AR22: =AQ22 -> 182 | ... AT22: =AS22 -> 182
C23: Отруби/шрот | D23: кг | R23: 1 | S23: 0 | T23: 0 | U23: 0 | V23: 0 | W23: 0 | X23: 0 | Y23: 1 | Z23: 1 | AA23: 1 | AB23: 1 | AC23: 1 | AD23: 1 | AE23: 0 | AF23: 0 | AG23: 0 | AI23: =SUMPRODUCT(J23:N23,J$4:N$4) -> 0 | AJ23: =SUMPRODUCT(O23:Z23,O$4:Z$4) -> 91 | AK23: =AJ23 -> 91 | AL23: =AK23 -> 91 | AM23: =AL23 -> 91 | AN23: =AM23 -> 91 | AO23: =AN23 -> 91 | AP23: =AO23 -> 91 | AQ23: =AP23 -> 91 | AR23: =AQ23 -> 91 | ... AT23: =AS23 -> 91
C24: Диаммонийфосфат (премикс) | D24: кг | R24: 0.03 | S24: 0 | T24: 0 | U24: 0 | V24: 0 | W24: 0 | X24: 0 | Y24: 0.04 | Z24: 0.04 | AA24: 0.03 | AB24: 0.03 | AC24: 0.03 | AD24: 0.03 | AE24: 0 | AF24: 0 | AG24: 0 | AI24: =SUMPRODUCT(J24:N24,J$4:N$4) -> 0 | AJ24: =SUMPRODUCT(O24:Z24,O$4:Z$4) -> 3.34 | AK24: =AJ24 -> 3.34 | AL24: =AK24 -> 3.34 | AM24: =AL24 -> 3.34 | AN24: =AM24 -> 3.34 | AO24: =AN24 -> 3.34 | AP24: =AO24 -> 3.34 | AQ24: =AP24 -> 3.34 | AR24: =AQ24 -> 3.34 | ... AT24: =AS24 -> 3.34
C25: Монокальцийфосфат (премикс) | D25: кг | R25: 0.055 | S25: 0 | T25: 0 | U25: 0 | V25: 0 | W25: 0 | X25: 0 | Y25: 0.045 | Z25: 0.045 | AA25: 0.055 | AB25: 0.055 | AC25: 0.055 | AD25: 0.055 | AE25: 0 | AF25: 0 | AG25: 0 | AI25: =SUMPRODUCT(J25:N25,J$4:N$4) -> 0 | AJ25: =SUMPRODUCT(O25:Z25,O$4:Z$4) -> 4.395 | AK25: =AJ25 -> 4.395 | AL25: =AK25 -> 4.395 | AM25: =AL25 -> 4.395 | AN25: =AM25 -> 4.395 | AO25: =AN25 -> 4.395 | AP25: =AO25 -> 4.395 | AQ25: =AP25 -> 4.395 | AR25: =AQ25 -> 4.395 | ... AT25: =AS25 -> 4.395
B27: Быки-производители | M27: =M28*M4 -> 0 | N27: =N28*N4 -> 0
C28: Зеленая масса | D28: кг | J28: 12 | K28: 12 | L28: 12 | M28: 0 | N28: 0 | O28: 0 | P28: 0 | Q28: 0 | R28: 0 | S28: 12 | T28: 12 | U28: 12 | V28: 12 | W28: 12 | X28: 12 | Y28: 0 | Z28: 0 | AA28: 0 | AB28: 0 | AC28: 0 | AD28: 0 | AE28: 12 | AF28: 12 | AG28: 12 | AI28: =SUMPRODUCT(J28:N28,J$4:N$4) -> 1092 | AJ28: =SUMPRODUCT(O28:Z28,O$4:Z$4) -> 2208 | AK28: =AJ28 -> 2208 | AL28: =AK28 -> 2208 | AM28: =AL28 -> 2208 | AN28: =AM28 -> 2208 | AO28: =AN28 -> 2208 | AP28: =AO28 -> 2208 | AQ28: =AP28 -> 2208 | AR28: =AQ28 -> 2208 | ... AT28: =AS28 -> 2208
C29: Сено | D29: кг | J29: 0 | K29: 0 | L29: 0 | M29: 8 | N29: 8 | O29: 8 | P29: 8 | Q29: 8 | R29: 8 | S29: 0 | T29: 0 | U29: 0 | V29: 0 | W29: 0 | X29: 0 | Y29: 8 | Z29: 8 | AA29: 8 | AB29: 8 | AC29: 8 | AD29: 8 | AE29: 0 | AF29: 0 | AG29: 0 | AI29: =SUMPRODUCT(J29:N29,J$4:N$4) -> 488 | AJ29: =SUMPRODUCT(O29:Z29,O$4:Z$4) -> 1448 | AK29: =AJ29 -> 1448 | AL29: =AK29 -> 1448 | AM29: =AL29 -> 1448 | AN29: =AM29 -> 1448 | AO29: =AN29 -> 1448 | AP29: =AO29 -> 1448 | AQ29: =AP29 -> 1448 | AR29: =AQ29 -> 1448 | ... AT29: =AS29 -> 1448
C30: Отруби/шрот | D30: кг | J30: 0 | K30: 0 | L30: 0 | M30: 1 | N30: 1 | O30: 1 | P30: 1 | Q30: 1 | R30: 1 | S30: 0 | T30: 0 | U30: 0 | V30: 0 | W30: 0 | X30: 0 | Y30: 1 | Z30: 1 | AA30: 1 | AB30: 1 | AC30: 1 | AD30: 1 | AE30: 0 | AF30: 0 | AG30: 0 | AI30: =SUMPRODUCT(J30:N30,J$4:N$4) -> 61 | AJ30: =SUMPRODUCT(O30:Z30,O$4:Z$4) -> 181 | AK30: =AJ30 -> 181 | AL30: =AK30 -> 181 | AM30: =AL30 -> 181 | AN30: =AM30 -> 181 | AO30: =AN30 -> 181 | AP30: =AO30 -> 181 | AQ30: =AP30 -> 181 | AR30: =AQ30 -> 181 | ... AT30: =AS30 -> 181
C31: Концентраты | D31: кг | J31: 0 | K31: 0 | L31: 0 | M31: =3.5-0.72 -> 2.78 | N31: =3.5-0.72 -> 2.78 | O31: =3.5-0.72 -> 2.78 | P31: =3.5-0.72 -> 2.78 | Q31: =3.5-0.72 -> 2.78 | R31: =3.5-0.72 -> 2.78 | S31: 0 | T31: 0 | U31: 0 | V31: 0 | W31: 0 | X31: 0 | Y31: =3.5-0.72 -> 2.78 | Z31: =3.5-0.72 -> 2.78 | AA31: =3.5-0.72 -> 2.78 | AB31: =3.5-0.72 -> 2.78 | AC31: =3.5-0.72 -> 2.78 | AD31: =3.5-0.72 -> 2.78 | AE31: 0 | AF31: 0 | AG31: 0 | AI31: =SUMPRODUCT(J31:N31,J$4:N$4) -> 169.58 | AJ31: =SUMPRODUCT(O31:Z31,O$4:Z$4) -> 503.18 | AK31: =AJ31 -> 503.18 | AL31: =AK31 -> 503.18 | AM31: =AL31 -> 503.18 | AN31: =AM31 -> 503.18 | AO31: =AN31 -> 503.18 | AP31: =AO31 -> 503.18 | AQ31: =AP31 -> 503.18 | AR31: =AQ31 -> 503.18 | ... AT31: =AS31 -> 503.18
C32: БМВД (премикс) | D32: кг | J32: 0 | K32: 0 | L32: 0 | M32: 0.72 | N32: 0.72 | O32: 0.72 | P32: 0.72 | Q32: 0.72 | R32: 0.72 | S32: 0 | T32: 0 | U32: 0 | V32: 0 | W32: 0 | X32: 0 | Y32: 0.72 | Z32: 0.72 | AA32: 0.72 | AB32: 0.72 | AC32: 0.72 | AD32: 0.72 | AE32: 0 | AF32: 0 | AG32: 0 | AI32: =SUMPRODUCT(J32:N32,J$4:N$4) -> 43.92 | AJ32: =SUMPRODUCT(O32:Z32,O$4:Z$4) -> 130.32 | AK32: =AJ32 -> 130.32 | AL32: =AK32 -> 130.32 | AM32: =AL32 -> 130.32 | AN32: =AM32 -> 130.32 | AO32: =AN32 -> 130.32 | AP32: =AO32 -> 130.32 | AQ32: =AP32 -> 130.32 | AR32: =AQ32 -> 130.32 | ... AT32: =AS32 -> 130.32
C33: Соль поваренная | D33: кг | J33: 0.05 | K33: 0.05 | L33: 0.05 | M33: 0.045 | N33: 0.045 | O33: 0.045 | P33: 0.045 | Q33: 0.045 | R33: 0.045 | S33: 0.05 | T33: 0.05 | U33: 0.05 | V33: 0.05 | W33: 0.05 | X33: 0.05 | Y33: 0.045 | Z33: 0.045 | AA33: 0.045 | AB33: 0.045 | AC33: 0.045 | AD33: 0.045 | AE33: 0.05 | AF33: 0.05 | AG33: 0.05 | AI33: =SUMPRODUCT(J33:N33,J$4:N$4) -> 7.295 | AJ33: =SUMPRODUCT(O33:Z33,O$4:Z$4) -> 17.345 | AK33: =AJ33 -> 17.345 | AL33: =AK33 -> 17.345 | AM33: =AL33 -> 17.345 | AN33: =AM33 -> 17.345 | AO33: =AN33 -> 17.345 | AP33: =AO33 -> 17.345 | AQ33: =AP33 -> 17.345 | AR33: =AQ33 -> 17.345 | ... AT33: =AS33 -> 17.345
B35: Молодняк
C36: Молоко | D36: л | J36: 0 | K36: 0 | L36: 0 | M36: 0 | N36: 6 | O36: 7 | P36: 6 | Q36: 5 | R36: 4 | S36: 4 | T36: 5 | U36: 0 | V36: 0 | W36: 0 | X36: 0 | Y36: 0 | Z36: 6 | AA36: 7 | AB36: 6 | AC36: 5 | AD36: 4 | AE36: 4 | AF36: 5 | AG36: 5 | AI36: =SUMPRODUCT(J36:N36,J$4:N$4) -> 186 | AJ36: =SUMPRODUCT(O36:Z36,O$4:Z$4) -> 1120 | AK36: =AJ36 -> 1120 | AL36: =AK36 -> 1120 | AM36: =AL36 -> 1120 | AN36: =AM36 -> 1120 | AO36: =AN36 -> 1120 | AP36: =AO36 -> 1120 | AQ36: =AP36 -> 1120 | AR36: =AQ36 -> 1120 | ... AT36: =AS36 -> 1120
C37: Сено | D37: кг | J37: 0 | K37: 0 | L37: 0 | M37: 0 | N37: 0 | O37: 0.3 | P37: 0.5 | Q37: 1 | R37: 1.2 | S37: 0 | T37: 0 | U37: 0 | V37: 0 | W37: 0 | X37: 0 | Y37: 0 | Z37: 0 | AA37: 0.3 | AB37: 0.5 | AC37: 1 | AD37: 1.2 | AE37: 0 | AF37: 0 | AG37: 0 | AI37: =SUMPRODUCT(J37:N37,J$4:N$4) -> 0 | AJ37: =SUMPRODUCT(O37:Z37,O$4:Z$4) -> 90.3 | AK37: =AJ37 -> 90.3 | AL37: =AK37 -> 90.3 | AM37: =AL37 -> 90.3 | AN37: =AM37 -> 90.3 | AO37: =AN37 -> 90.3 | AP37: =AO37 -> 90.3 | AQ37: =AP37 -> 90.3 | AR37: =AQ37 -> 90.3 | ... AT37: =AS37 -> 90.3
C38: Силос | D38: кг | J38: 0 | K38: 0 | L38: 0 | M38: 0 | N38: 0 | O38: 0 | P38: 0 | Q38: 0 | R38: 0 | S38: 0 | T38: 0 | U38: 0 | V38: 0 | W38: 0 | X38: 0 | Y38: 0 | Z38: 0 | AA38: 0 | AB38: 0 | AC38: 0 | AD38: 0 | AE38: 0 | AF38: 0 | AG38: 0 | AI38: =SUMPRODUCT(J38:N38,J$4:N$4) -> 0 | AJ38: =SUMPRODUCT(O38:Z38,O$4:Z$4) -> 0 | AK38: =AJ38 -> 0 | AL38: =AK38 -> 0 | AM38: =AL38 -> 0 | AN38: =AM38 -> 0 | AO38: =AN38 -> 0 | AP38: =AO38 -> 0 | AQ38: =AP38 -> 0 | AR38: =AQ38 -> 0 | ... AT38: =AS38 -> 0
C39: Концентраты | D39: кг | J39: 0 | K39: 0 | L39: 0 | M39: 0 | N39: 0 | O39: 0.2 | P39: 0.4 | Q39: 0.6 | R39: 0.7 | S39: 0 | T39: 0 | U39: 0 | V39: 0 | W39: 0 | X39: 0 | Y39: 0 | Z39: 0 | AA39: 0.2 | AB39: 0.4 | AC39: 0.6 | AD39: 0.7 | AE39: 0 | AF39: 0 | AG39: 0 | AI39: =SUMPRODUCT(J39:N39,J$4:N$4) -> 0 | AJ39: =SUMPRODUCT(O39:Z39,O$4:Z$4) -> 57 | AK39: =AJ39 -> 57 | AL39: =AK39 -> 57 | AM39: =AL39 -> 57 | AN39: =AM39 -> 57 | AO39: =AN39 -> 57 | AP39: =AO39 -> 57 | AQ39: =AP39 -> 57 | AR39: =AQ39 -> 57 | ... AT39: =AS39 -> 57
C40: Соль поваренная | D40: кг | J40: 0 | K40: 0 | L40: 0 | M40: 0 | N40: 0 | O40: 0.008 | P40: 0.012 | Q40: 0.016 | R40: 0.018 | S40: 0.022 | T40: 0.027 | U40: 0 | V40: 0 | W40: 0 | X40: 0 | Y40: 0 | Z40: 0 | AA40: 0.008 | AB40: 0.012 | AC40: 0.016 | AD40: 0.018 | AE40: 0.022 | AF40: 0.027 | AG40: 0.027 | AI40: =SUMPRODUCT(J40:N40,J$4:N$4) -> 0 | AJ40: =SUMPRODUCT(O40:Z40,O$4:Z$4) -> 3.112 | AK40: =AJ40 -> 3.112 | AL40: =AK40 -> 3.112 | AM40: =AL40 -> 3.112 | AN40: =AM40 -> 3.112 | AO40: =AN40 -> 3.112 | AP40: =AO40 -> 3.112 | AQ40: =AP40 -> 3.112 | AR40: =AQ40 -> 3.112 | ... AT40: =AS40 -> 3.112
C41: Кормовой фосфат | D41: кг | J41: 0 | K41: 0 | L41: 0 | M41: 0 | N41: 0 | O41: 0.01 | P41: 0.02 | Q41: 0.03 | R41: 0.03 | S41: 0.04 | T41: 0.03 | U41: 0 | V41: 0 | W41: 0 | X41: 0 | Y41: 0 | Z41: 0 | AA41: 0.01 | AB41: 0.02 | AC41: 0.03 | AD41: 0.03 | AE41: 0.04 | AF41: 0.03 | AG41: 0.03 | AI41: =SUMPRODUCT(J41:N41,J$4:N$4) -> 0 | AJ41: =SUMPRODUCT(O41:Z41,O$4:Z$4) -> 4.84 | AK41: =AJ41 -> 4.84 | AL41: =AK41 -> 4.84 | AM41: =AL41 -> 4.84 | AN41: =AM41 -> 4.84 | AO41: =AN41 -> 4.84 | AP41: =AO41 -> 4.84 | AQ41: =AP41 -> 4.84 | AR41: =AQ41 -> 4.84 | ... AT41: =AS41 -> 4.84
C42: Зеленая масса | D42: кг | J42: 0 | K42: 0 | L42: 0 | M42: 0 | N42: 0 | O42: 0 | P42: 0 | Q42: 0 | R42: 0 | S42: 0 | T42: 9 | U42: 0 | V42: 0 | W42: 0 | X42: 0 | Y42: 0 | Z42: 0 | AA42: 0 | AB42: 0 | AC42: 0 | AD42: 0 | AE42: 0 | AF42: 9 | AG42: 9 | AI42: =SUMPRODUCT(J42:N42,J$4:N$4) -> 0 | AJ42: =SUMPRODUCT(O42:Z42,O$4:Z$4) -> 270 | AK42: =AJ42 -> 270 | AL42: =AK42 -> 270 | AM42: =AL42 -> 270 | AN42: =AM42 -> 270 | AO42: =AN42 -> 270 | AP42: =AO42 -> 270 | AQ42: =AP42 -> 270 | AR42: =AQ42 -> 270 | ... AT42: =AS42 -> 270
B44: Телочки предыдущего периода
C45: Зеленая масса | D45: кг | J45: 29 | K45: 29 | L45: 29 | M45: 0 | N45: 0 | O45: 0 | P45: 0 | Q45: 0 | AI45: =SUMPRODUCT(J45:N45,J$4:N$4) -> 2639 | AJ45: =SUMPRODUCT(O45:Z45,O$4:Z$4) -> 0 | AK45: =AJ45 -> 0 | AL45: =AK45 -> 0 | AM45: =AL45 -> 0 | AN45: =AM45 -> 0 | AO45: =AN45 -> 0 | AP45: =AO45 -> 0 | AQ45: =AP45 -> 0 | AR45: =AQ45 -> 0 | ... AT45: =AS45 -> 0
C46: Концентраты | D46: кг | J46: 0 | K46: 0 | L46: 0 | M46: 0 | N46: 0 | O46: 0 | P46: 0 | Q46: 0 | AI46: =SUMPRODUCT(J46:N46,J$4:N$4) -> 0 | AJ46: =SUMPRODUCT(O46:Z46,O$4:Z$4) -> 0 | AK46: =AJ46 -> 0 | AL46: =AK46 -> 0 | AM46: =AL46 -> 0 | AN46: =AM46 -> 0 | AO46: =AN46 -> 0 | AP46: =AO46 -> 0 | AQ46: =AP46 -> 0 | AR46: =AQ46 -> 0 | ... AT46: =AS46 -> 0
...

Sheet Loans
B1: Займы Большой Фермы Управляющей компании
B2: Дата выдачи | E2: 46235
B3: Сумма займа АКК | D3: тыс. тенге | E3: =Input!G56 -> 358330.37
B4: Ставка вознагр. | D4: % | E4: =Output!D190 -> 0.05
B5: Срок | D5: лет | E5: 10
B6: Льготный период | D6: лет | E6: 2
B8: Погашение процентов | D8: мес. | E8: 12 | G8: каждые 12 мес.
B9: Погашение ОД | D9: мес. | E9: 12 | G9: каждые 12 мес.
B11: Погашение ОД | D11: 2026 | E11: 0 | F11: =$E$3*E11 -> 0
D12: =D11+1 -> 2027 | E12: 0 | F12: =$E$3*E12 -> 0
C13: =100%/9 -> 0.11111111 | D13: =D12+1 -> 2028 | E13: 0.11 | F13: =$E$3*E13 -> 39416.341
D14: =D13+1 -> 2029 | E14: 0.11 | F14: =$E$3*E14 -> 39416.341
D15: =D14+1 -> 2030 | E15: 0.11 | F15: =$E$3*E15 -> 39416.341
D16: =D15+1 -> 2031 | E16: 0.11 | F16: =$E$3*E16 -> 39416.341
D17: =D16+1 -> 2032 | E17: 0.11 | F17: =$E$3*E17 -> 39416.341
D18: =D17+1 -> 2033 | E18: 0.11 | F18: =$E$3*E18 -> 39416.341
D19: =D18+1 -> 2034 | E19: 0.11 | F19: =$E$3*E19 -> 39416.341
D20: =D19+1 -> 2035 | E20: 0.11 | F20: =$E$3*E20 -> 39416.341
D21: =D20+1 -> 2036 | E21: =100%-SUM(E11:E20) -> 0.12 | F21: =$E$3*E21 -> 42999.645
E22: =SUM(E11:E21) -> 1 | F22: =SUM(F11:F21) -> 358330.37
J23: =YEAR(J26) -> 2026 | K23: =YEAR(K26) -> 2026 | L23: =YEAR(L26) -> 2026 | M23: =YEAR(M26) -> 2026 | N23: =YEAR(N26) -> 2026 | O23: =YEAR(O26) -> 2027 | P23: =YEAR(P26) -> 2027 | Q23: =YEAR(Q26) -> 2027 | ... DY23: =YEAR(DY26) -> 2036
J24: 1 | K24: =J24+1 -> 2 | L24: =K24+1 -> 3 | M24: =L24+1 -> 4 | N24: =M24+1 -> 5 | O24: =N24+1 -> 6 | P24: =O24+1 -> 7 | Q24: =P24+1 -> 8 | R24: =Q24+1 -> 9 | ... DY24: =DX24+1 -> 120
A25: х | B25: График финансовых обязательств
B26: Инвестиционный кредит | J26: ='Operating Model'!J280 -> 46265 | K26: =EDATE(J26,1) -> 46295 | L26: =EDATE(K26,1) -> 46325 | M26: =EDATE(L26,1) -> 46356 | N26: =EDATE(M26,1) -> 46386 | O26: =EDATE(N26,1) -> 46417 | P26: =EDATE(O26,1) -> 46446 | Q26: =EDATE(P26,1) -> 46474 | R26: =EDATE(Q26,1) -> 46505 | ... DY26: =EDATE(DX26,1) -> 49884
B27: Средства доступные для погашения займа БВУ | D27: тыс. тенге
B28: Сумма займа БВУ | D28: тыс. тенге | J28: =E3 -> 358330.37
B31: ОД на начало | D31: тыс. тенге | J31: =E3 -> 358330.37 | K31: =J37 -> 358330.37 | L31: =K37 -> 358330.37 | M31: =L37 -> 358330.37 | N31: =M37 -> 358330.37 | O31: =N37 -> 358330.37 | P31: =O37 -> 358330.37 | Q31: =P37 -> 358330.37 | R31: =Q37 -> 358330.37 | ... DY31: =DX37 -> 42999.645
B32: Начисление процентов | D32: тыс. тенге | J32: =J31*$E$4*(J26-E2)/365 -> 1472.5906 | K32: =K31*$E$4*(K26-J26)/365 -> 1472.5906 | L32: =L31*$E$4*(L26-K26)/365 -> 1472.5906 | M32: =M31*$E$4*(M26-L26)/365 -> 1521.6769 | N32: =N31*$E$4*(N26-M26)/365 -> 1472.5906 | O32: =O31*$E$4*(O26-N26)/365 -> 1521.6769 | P32: =P31*$E$4*(P26-O26)/365 -> 1423.5042 | Q32: =Q31*$E$4*(Q26-P26)/365 -> 1374.4179 | R32: =R31*$E$4*(R26-Q26)/365 -> 1521.6769 | ... DY32: =DY31*$E$4*(DY26-DX26)/365 -> 176.71087
B33: Погашение процентов | D33: тыс. тенге | J33: 0 | K33: 0 | L33: 0 | M33: 0 | N33: 0 | O33: 0 | P33: 0 | Q33: 0 | R33: 0 | S33: 0 | T33: 0 | U33: 0 | V33: 0 | W33: 0 | X33: 0 | Y33: 0 | Z33: 0 | AA33: 0 | AB33: 0 | AC33: 0 | AD33: 0 | AE33: 0 | AF33: 0 | AG33: =AG34*(1/9) -> 3965.0865 | AH33: 0 | AI33: 0 | AJ33: 0 | AK33: 0 | AL33: 0 | AM33: 0 | AN33: 0 | AO33: 0 | AP33: 0 | AQ33: 0 | AR33: 0 | AS33: =SUM(AH32:AS32)+$AG$33 -> 19910.788 | AT33: 0 | AU33: 0 | AV33: 0 | AW33: 0 | AX33: 0 | AY33: 0 | AZ33: 0 | BA33: 0 | BB33: 0 | BC33: 0 | BD33: 0 | BE33: =SUM(AT32:BE32)+$AG$33 -> 17939.971 | BF33: 0 | BG33: 0 | BH33: 0 | BI33: 0 | BJ33: 0 | BK33: 0 | BL33: 0 | BM33: 0 | BN33: 0 | BO33: 0 | BP33: 0 | BQ33: =SUM(BF32:BQ32)+$AG$33 -> 15969.154 | BR33: 0 | BS33: 0 | BT33: 0 | BU33: 0 | BV33: 0 | BW33: 0 | BX33: 0 | BY33: 0 | BZ33: 0 | CA33: 0 | CB33: 0 | CC33: =SUM(BR32:CC32)+$AG$33 -> 14025.825 | CD33: 0 | CE33: 0 | CF33: 0 | CG33: 0 | CH33: 0 | CI33: 0 | CJ33: 0 | CK33: 0 | CL33: 0 | CM33: 0 | CN33: 0 | CO33: =SUM(CD32:CO32)+$AG$33 -> 12027.52 | CP33: 0 | CQ33: 0 | CR33: 0 | CS33: 0 | CT33: 0 | CU33: 0 | CV33: 0 | CW33: 0 | CX33: 0 | CY33: 0 | CZ33: 0 | DA33: =SUM(CP32:DA32)+$AG$33 -> 10056.703 | DB33: 0 | DC33: 0 | DD33: 0 | DE33: 0 | DF33: 0 | DG33: 0 | DH33: 0 | DI33: 0 | DJ33: 0 | DK33: 0 | DL33: 0 | DM33: =SUM(DB32:DM32)+$AG$33 -> 8085.8858 | DN33: 0 | DO33: 0 | DP33: 0 | DQ33: 0 | DR33: 0 | DS33: 0 | DT33: 0 | DU33: 0 | DV33: 0 | DW33: 0 | DX33: 0 | DY33: =SUM(DN32:DY32)+$AG$33 -> 6120.9591
AG34: =SUM(J32:AG32) -> 35685.778 | AS34: =SUM(AH32:AS32) -> 15945.702
B35: Накопленные проценты | D35: тыс. тенге | J35: =J32-J33 -> 1472.5906 | K35: =K32-K33+J35 -> 2945.1812 | L35: =L32-L33+K35 -> 4417.7717 | M35: =M32-M33+L35 -> 5939.4487 | N35: =N32-N33+M35 -> 7412.0392 | O35: =O32-O33+N35 -> 8933.7162 | P35: =P32-P33+O35 -> 10357.22 | Q35: =Q32-Q33+P35 -> 11731.638 | R35: =R32-R33+Q35 -> 13253.315 | ... DY35: =DY32-DY33+DX35 -> -1.4551915e-11
B36: Погашение ОД (10 лет - льготный период 2 года) | D36: тыс. тенге | J36: 0 | K36: 0 | L36: 0 | M36: 0 | N36: 0 | O36: 0 | P36: 0 | Q36: 0 | R36: 0 | S36: 0 | T36: 0 | U36: 0 | V36: 0 | W36: 0 | X36: 0 | Y36: 0 | Z36: 0 | AA36: 0 | AB36: 0 | AC36: 0 | AD36: 0 | AE36: 0 | AF36: 0 | AG36: =F13 -> 39416.341 | AH36: 0 | AI36: 0 | AJ36: 0 | AK36: 0 | AL36: 0 | AM36: 0 | AN36: 0 | AO36: 0 | AP36: 0 | AQ36: 0 | AR36: 0 | AS36: =F14 -> 39416.341 | AT36: 0 | AU36: 0 | AV36: 0 | AW36: 0 | AX36: 0 | AY36: 0 | AZ36: 0 | BA36: 0 | BB36: 0 | BC36: 0 | BD36: 0 | BE36: =F15 -> 39416.341 | BF36: 0 | BG36: 0 | BH36: 0 | BI36: 0 | BJ36: 0 | BK36: 0 | BL36: 0 | BM36: 0 | BN36: 0 | BO36: 0 | BP36: 0 | BQ36: =F16 -> 39416.341 | BR36: 0 | BS36: 0 | BT36: 0 | BU36: 0 | BV36: 0 | BW36: 0 | BX36: 0 | BY36: 0 | BZ36: 0 | CA36: 0 | CB36: 0 | CC36: =F17 -> 39416.341 | CD36: 0 | CE36: 0 | CF36: 0 | CG36: 0 | CH36: 0 | CI36: 0 | CJ36: 0 | CK36: 0 | CL36: 0 | CM36: 0 | CN36: 0 | CO36: =F18 -> 39416.341 | CP36: 0 | CQ36: 0 | CR36: 0 | CS36: 0 | CT36: 0 | CU36: 0 | CV36: 0 | CW36: 0 | CX36: 0 | CY36: 0 | CZ36: 0 | DA36: =F19 -> 39416.341 | DB36: 0 | DC36: 0 | DD36: 0 | DE36: 0 | DF36: 0 | DG36: 0 | DH36: 0 | DI36: 0 | DJ36: 0 | DK36: 0 | DL36: 0 | DM36: =F20 -> 39416.341 | DN36: 0 | DO36: 0 | DP36: 0 | DQ36: 0 | DR36: 0 | DS36: 0 | DT36: 0 | DU36: 0 | DV36: 0 | DW36: 0 | DX36: 0 | DY36: =F21 -> 42999.645
B37: ОД на конец | D37: тыс. тенге | J37: =J31-J36 -> 358330.37 | K37: =K31-K36 -> 358330.37 | L37: =L31-L36 -> 358330.37 | M37: =M31-M36 -> 358330.37 | N37: =N31-N36 -> 358330.37 | O37: =O31-O36 -> 358330.37 | P37: =P31-P36 -> 358330.37 | Q37: =Q31-Q36 -> 358330.37 | ... DY37: =DY31-DY36 -> -7.2759576e-11
B43: Займы 2ой год
B44: Дата выдачи | E44: 46235
B45: Сумма займа АКК | D45: тыс. тенге | E45: =Input!K56 -> 0
B46: Ставка вознагр. | D46: % | E46: =Output!L190 -> 0
B47: Срок | D47: лет | E47: 10
B48: Льготный период | D48: лет | E48: 2
B50: Погашение процентов | D50: мес. | E50: 12 | G50: каждые 12 мес.
...

Sheet Staff
AI1: ='Operating Model'!AI2 -> 46387 | AJ1: ='Operating Model'!AJ2 -> 46752 | AK1: ='Operating Model'!AK2 -> 47118 | AL1: ='Operating Model'!AL2 -> 47483 | AM1: ='Operating Model'!AM2 -> 47848 | AN1: ='Operating Model'!AN2 -> 48213 | AO1: ='Operating Model'!AO2 -> 48579 | AP1: ='Operating Model'!AP2 -> 48944 | ... AT1: ='Operating Model'!AT2 -> 50405
A2: х | B2: Расчет заработной платы
A4: х | B4: Макроэкономические показатели
J5: =J13 -> 46265 | K5: =EOMONTH(J5,1) -> 46295 | L5: =EOMONTH(K5,1) -> 46326 | M5: =EOMONTH(L5,1) -> 46356 | N5: =EOMONTH(M5,1) -> 46387 | O5: =EOMONTH(N5,1) -> 46418 | P5: =EOMONTH(O5,1) -> 46446 | Q5: =EOMONTH(P5,1) -> 46477 | R5: =EOMONTH(Q5,1) -> 46507 | ... AG5: =EOMONTH(AF5,1) -> 46965 | AI5: =AI13 -> 2026 | AJ5: =AJ13 -> 2027 | AK5: =AK13 -> 2028 | AL5: =AL13 -> 2029 | AM5: =AM13 -> 2030 | AN5: =AN13 -> 2031 | AO5: =AO13 -> 2032 | AP5: =AP13 -> 2033 | ... AT5: =AT13 -> 2037
B6: ИПЦ в KZ, ср. | D6: % | E6: https://www.imf.org/external/datamapper/profile/KAZ | F6: IMF | J6: =AI6 -> 0.11 | K6: 0 | L6: =K6 -> 0 | M6: =L6 -> 0 | N6: =M6 -> 0 | O6: =AJ6 -> 0.105 | P6: 0 | Q6: =P6 -> 0 | R6: =Q6 -> 0 | S6: =R6 -> 0 | T6: =S6 -> 0 | U6: =T6 -> 0 | V6: =U6 -> 0 | W6: =V6 -> 0 | X6: =W6 -> 0 | ... Z6: =Y6 -> 0 | AA6: =AK6 -> 0.1 | AB6: 0 | AC6: =AB6 -> 0 | AD6: =AC6 -> 0 | AE6: =AD6 -> 0 | AF6: =AE6 -> 0 | AG6: =AF6 -> 0 | AI6: ='Operating Model'!AI31 -> 0.11 | AJ6: ='Operating Model'!AJ31 -> 0.105 | AK6: ='Operating Model'!AK31 -> 0.1 | AL6: ='Operating Model'!AL31 -> 0.095 | AM6: ='Operating Model'!AM31 -> 0.09 | AN6: ='Operating Model'!AN31 -> 0.085 | AO6: ='Operating Model'!AO31 -> 0.08 | AP6: ='Operating Model'!AP31 -> 0.07 | ... AT6: ='Operating Model'!AT31 -> 0.05
C7: Фактор | G7: =1/12 -> 0.083333333
A9: х | B9: Налоговые ставки
J10: 1 | K10: =J10+1 -> 2 | L10: =K10+1 -> 3 | M10: =L10+1 -> 4 | N10: =M10+1 -> 5 | O10: =N10+1 -> 6 | P10: =O10+1 -> 7 | Q10: =P10+1 -> 8 | R10: =Q10+1 -> 9 | ... AG10: =AF10+1 -> 24 | AI10: 5 | AJ10: 12 | AK10: 12 | AL10: 12 | AM10: 12 | AN10: 12 | AO10: 12 | AP10: 12 | AQ10: 12 | AR10: 12 | AS10: 12 | AT10: 12
J12: =YEAR(J14) -> 2026 | K12: =YEAR(K14) -> 2026 | L12: =YEAR(L14) -> 2026 | M12: =YEAR(M14) -> 2026 | N12: =YEAR(N14) -> 2026 | O12: =YEAR(O14) -> 2027 | P12: =YEAR(P14) -> 2027 | Q12: =YEAR(Q14) -> 2027 | ... AG12: =YEAR(AG14) -> 2028 | AI12: =YEAR(AI14) -> 2026 | AJ12: =YEAR(AJ14) -> 2027 | AK12: =YEAR(AK14) -> 2028 | AL12: =YEAR(AL14) -> 2029 | AM12: =YEAR(AM14) -> 2030 | AN12: =YEAR(AN14) -> 2031 | AO12: =YEAR(AO14) -> 2032 | AP12: =YEAR(AP14) -> 2033 | ... AT12: =YEAR(AT14) -> 2037
E13: Год | G13: Месяц | J13: 46265 | K13: =EDATE(J13,1) -> 46295 | L13: =EDATE(K13,1) -> 46325 | M13: =EDATE(L13,1) -> 46356 | N13: =EDATE(M13,1) -> 46386 | O13: =EDATE(N13,1) -> 46417 | P13: =EDATE(O13,1) -> 46446 | Q13: =EDATE(P13,1) -> 46474 | R13: =EDATE(Q13,1) -> 46505 | ... AG13: =EDATE(AF13,1) -> 46962 | AI13: =YEAR(AI1) -> 2026 | AJ13: =YEAR(AJ1) -> 2027 | AK13: =YEAR(AK1) -> 2028 | AL13: =YEAR(AL1) -> 2029 | AM13: =YEAR(AM1) -> 2030 | AN13: =YEAR(AN1) -> 2031 | AO13: =YEAR(AO1) -> 2032 | AP13: =YEAR(AP1) -> 2033 | ... AT13: =YEAR(AT1) -> 2037
J14: 46265 | K14: =EOMONTH(J14,1) -> 46295 | L14: =EOMONTH(K14,1) -> 46326 | M14: =EOMONTH(L14,1) -> 46356 | N14: =EOMONTH(M14,1) -> 46387 | O14: =EOMONTH(N14,1) -> 46418 | P14: =EOMONTH(O14,1) -> 46446 | Q14: =EOMONTH(P14,1) -> 46477 | R14: =EOMONTH(Q14,1) -> 46507 | ... AG14: =EOMONTH(AF14,1) -> 46965 | AI14: 46387 | AJ14: =EOMONTH(AI14,12) -> 46752 | AK14: =EOMONTH(AJ14,12) -> 47118 | AL14: =EOMONTH(AK14,12) -> 47483 | AM14: =EOMONTH(AL14,12) -> 47848 | AN14: =EOMONTH(AM14,12) -> 48213 | AO14: =EOMONTH(AN14,12) -> 48579 | AP14: =EOMONTH(AO14,12) -> 48944 | AQ14: =EOMONTH(AP14,12) -> 49309 | ... AT14: =EOMONTH(AS14,12) -> 50405
C16: Месячный расчетный показатель | D16: тенге | J16: 3932 | K16: 3932 | L16: 3932 | M16: 3932 | N16: 3932 | O16: =N16*(1+O$6) -> 4344.86 | P16: =O16 -> 4344.86 | Q16: =P16 -> 4344.86 | R16: =Q16 -> 4344.86 | S16: =R16 -> 4344.86 | T16: =S16 -> 4344.86 | U16: =T16 -> 4344.86 | V16: =U16 -> 4344.86 | W16: =V16 -> 4344.86 | ... Z16: =Y16 -> 4344.86 | AA16: =Z16*(1+AA6) -> 4779.346 | AB16: =AA16 -> 4779.346 | AC16: =AB16 -> 4779.346 | AD16: =AC16 -> 4779.346 | AE16: =AD16 -> 4779.346 | AF16: =AE16 -> 4779.346 | AG16: =AF16 -> 4779.346 | AI16: 3932 | AJ16: =AI16*(1+AJ6) -> 4344.86 | AK16: =AJ16*(1+AK6) -> 4779.346 | AL16: =AK16*(1+AL6) -> 5233.3839 | AM16: =AL16*(1+AM6) -> 5704.3884 | AN16: =AM16*(1+AN6) -> 6189.2614 | AO16: =AN16*(1+AO6) -> 6684.4023 | AP16: =AO16*(1+AP6) -> 7152.3105 | AQ16: =AP16*(1+AQ6) -> 7617.2107 | ... AT16: =AS16*(1+AT6) -> 8901.8533
C17: Минимальная заработная плата | D17: тыс. тенге / мес. | J17: 93 | K17: =J17 -> 93 | L17: =K17 -> 93 | M17: =L17 -> 93 | N17: =M17 -> 93 | O17: =N17*(1+O$6) -> 102.765 | P17: =O17 -> 102.765 | Q17: =P17 -> 102.765 | R17: =Q17 -> 102.765 | S17: =R17 -> 102.765 | T17: =S17 -> 102.765 | U17: =T17 -> 102.765 | V17: =U17 -> 102.765 | W17: =V17 -> 102.765 | ... Z17: =Y17 -> 102.765 | AA17: =Z17*(1+AA$6) -> 113.0415 | AB17: =AA17 -> 113.0415 | AC17: =AB17 -> 113.0415 | AD17: =AC17 -> 113.0415 | AE17: =AD17 -> 113.0415 | AF17: =AE17 -> 113.0415 | AG17: =AF17 -> 113.0415 | AI17: 85 | AJ17: =AI17*(1+AJ$6) -> 93.925 | AK17: =AJ17*(1+AK$6) -> 103.3175 | AL17: =AK17*(1+AL$6) -> 113.13266 | AM17: =AL17*(1+AM$6) -> 123.3146 | AN17: =AM17*(1+AN$6) -> 133.79634 | AO17: =AN17*(1+AO$6) -> 144.50005 | AP17: =AO17*(1+AP$6) -> 154.61505 | AQ17: =AP17*(1+AQ$6) -> 164.66503 | ... AT17: =AS17*(1+AT$6) -> 192.43579
C18: Максимальный объект расчета исчислений (для СО) | D18: тыс. тенге / мес. | E18: Tax code, RoK | F18: 7 | J18: =$F18*J$17 -> 651 | K18: =$F18*K$17 -> 651 | L18: =$F18*L$17 -> 651 | M18: =$F18*M$17 -> 651 | N18: =$F18*N$17 -> 651 | O18: =$F18*O$17 -> 719.355 | P18: =$F18*P$17 -> 719.355 | Q18: =$F18*Q$17 -> 719.355 | ... AG18: =$F18*AG$17 -> 791.2905 | AI18: =$F18*AI$17 -> 595 | AJ18: =$F18*AJ$17 -> 657.475 | AK18: =$F18*AK$17 -> 723.2225 | AL18: =$F18*AL$17 -> 791.92864 | AM18: =$F18*AM$17 -> 863.20221 | AN18: =$F18*AN$17 -> 936.5744 | AO18: =$F18*AO$17 -> 1011.5004 | AP18: =$F18*AP$17 -> 1082.3054 | ... AT18: =$F18*AT$17 -> 1347.0505
C19: Максимальный объект расчета исчислений (для ОСМС) | D19: тыс. тенге / мес. | E19: Tax code, RoK | F19: 10 | J19: =$F19*J$17 -> 930 | K19: =$F19*K$17 -> 930 | L19: =$F19*L$17 -> 930 | M19: =$F19*M$17 -> 930 | N19: =$F19*N$17 -> 930 | O19: =$F19*O$17 -> 1027.65 | P19: =$F19*P$17 -> 1027.65 | Q19: =$F19*Q$17 -> 1027.65 | ... AG19: =$F19*AG$17 -> 1130.415 | AI19: =$F19*AI$17 -> 850 | AJ19: =$F19*AJ$17 -> 939.25 | AK19: =$F19*AK$17 -> 1033.175 | AL19: =$F19*AL$17 -> 1131.3266 | AM19: =$F19*AM$17 -> 1233.146 | AN19: =$F19*AN$17 -> 1337.9634 | AO19: =$F19*AO$17 -> 1445.0005 | AP19: =$F19*AP$17 -> 1546.1505 | ... AT19: =$F19*AT$17 -> 1924.3579
C20: Минимальный порог на вычеты | D20: МРП | F20: 300
C22: Уровень социальных отчислений | D22: % | E22: Tax code, RoK | F22: 0.035 | J22: =$F22 -> 0.035 | K22: =$F22 -> 0.035 | L22: =$F22 -> 0.035 | M22: =$F22 -> 0.035 | N22: =$F22 -> 0.035 | O22: =$F22 -> 0.035 | P22: =$F22 -> 0.035 | Q22: =$F22 -> 0.035 | ... AG22: =$F22 -> 0.035 | AI22: =$F22 -> 0.035 | AJ22: =$F22 -> 0.035 | AK22: =$F22 -> 0.035 | AL22: =$F22 -> 0.035 | AM22: =$F22 -> 0.035 | AN22: =$F22 -> 0.035 | AO22: =$F22 -> 0.035 | AP22: =$F22 -> 0.035 | ... AT22: =$F22 -> 0.035
C23: Уровень социального налога | D23: % | E23: Tax code, RoK | F23: 0.095 | J23: =$F23 -> 0.095 | K23: =$F23 -> 0.095 | L23: =$F23 -> 0.095 | M23: =$F23 -> 0.095 | N23: =$F23 -> 0.095 | O23: =$F23 -> 0.095 | P23: =$F23 -> 0.095 | Q23: =$F23 -> 0.095 | ... AG23: =$F23 -> 0.095 | AI23: =$F23 -> 0.095 | AJ23: =$F23 -> 0.095 | AK23: =$F23 -> 0.095 | AL23: =$F23 -> 0.095 | AM23: =$F23 -> 0.095 | AN23: =$F23 -> 0.095 | AO23: =$F23 -> 0.095 | AP23: =$F23 -> 0.095 | ... AT23: =$F23 -> 0.095
C24: Обязательное социальное медицинское страхование | D24: % | E24: Tax code, RoK | F24: 0.03 | J24: =$F24 -> 0.03 | K24: =$F24 -> 0.03 | L24: =$F24 -> 0.03 | M24: =$F24 -> 0.03 | N24: =$F24 -> 0.03 | O24: =$F24 -> 0.03 | P24: =$F24 -> 0.03 | Q24: =$F24 -> 0.03 | ... AG24: =$F24 -> 0.03 | AI24: =$F24 -> 0.03 | AJ24: =$F24 -> 0.03 | AK24: =$F24 -> 0.03 | AL24: =$F24 -> 0.03 | AM24: =$F24 -> 0.03 | AN24: =$F24 -> 0.03 | AO24: =$F24 -> 0.03 | AP24: =$F24 -> 0.03 | ... AT24: =$F24 -> 0.03
C25: Взносы ОСМС работников | D25: % | E25: Tax code, RoK | F25: 0.02 | J25: =$F25 -> 0.02 | K25: =$F25 -> 0.02 | L25: =$F25 -> 0.02 | M25: =$F25 -> 0.02 | N25: =$F25 -> 0.02 | O25: =$F25 -> 0.02 | P25: =$F25 -> 0.02 | Q25: =$F25 -> 0.02 | ... AG25: =$F25 -> 0.02 | AI25: =$F25 -> 0.02 | AJ25: =$F25 -> 0.02 | AK25: =$F25 -> 0.02 | AL25: =$F25 -> 0.02 | AM25: =$F25 -> 0.02 | AN25: =$F25 -> 0.02 | AO25: =$F25 -> 0.02 | AP25: =$F25 -> 0.02 | ... AT25: =$F25 -> 0.02
C27: Пенсионные отчисления | E27: Tax code, RoK | F27: 0.1
C29: Заработная плата
C30: Коэффициент с нэт ЗП в брутто ЗП (в случае резидента РК) | F30: 1.21
A32: х | B32: Результат - ФОТ
B34: ФОТ
B36: Производственный персонал | D36: тыс. тенге | J36: =SUM(J37:J40) -> 1940.3366 | K36: =SUM(K37:K40) -> 1940.3366 | L36: =SUM(L37:L40) -> 1940.3366 | M36: =SUM(M37:M40) -> 1940.3366 | N36: =SUM(N37:N40) -> 1940.3366 | O36: =SUM(O37:O40) -> 2144.072 | P36: =SUM(P37:P40) -> 2144.072 | Q36: =SUM(Q37:Q40) -> 2144.072 | ... AG36: =SUM(AG37:AG40) -> 2358.4792 | AI36: =SUM(AI37:AI40) -> -9701.6832 | AJ36: =SUM(AJ37:AJ40) -> -25728.864 | AK36: =SUM(AK37:AK40) -> -28301.75 | AL36: =SUM(AL37:AL40) -> -30990.417 | AM36: =SUM(AM37:AM40) -> -33779.554 | AN36: =SUM(AN37:AN40) -> -36650.816 | AO36: =SUM(AO37:AO40) -> -39582.881 | AP36: =SUM(AP37:AP40) -> -42353.683 | ... AT36: =SUM(AT37:AT40) -> -52713.913
C37: Персонал | D37: тыс. тенге | J37: =J93 -> 1742.4 | K37: =K93 -> 1742.4 | L37: =L93 -> 1742.4 | M37: =M93 -> 1742.4 | N37: =N93 -> 1742.4 | O37: =O93 -> 1925.352 | P37: =P93 -> 1925.352 | Q37: =Q93 -> 1925.352 | ... AG37: =AG93 -> 2117.8872 | AI37: =AI93 -> -8712 | AJ37: =AJ93 -> -23104.224 | AK37: =AK93 -> -25414.646 | AL37: =AL93 -> -27829.038 | AM37: =AM93 -> -30333.651 | AN37: =AN93 -> -32912.012 | AO37: =AO93 -> -35544.972 | AP37: =AP93 -> -38033.121 | ... AT37: =AT93 -> -47336.488
C38: Социальные отчисления | D38: тыс. тенге | J38: =J143 -> 58.28655 | K38: =K143 -> 58.28655 | L38: =L143 -> 58.28655 | M38: =M143 -> 58.28655 | N38: =N143 -> 58.28655 | O38: =O143 -> 64.414245 | P38: =P143 -> 64.414245 | Q38: =Q143 -> 64.414245 | ... AG38: =AG143 -> 70.862915 | AI38: =-AI143 -> -281.63275 | AJ38: =-AJ143 -> -746.98134 | AK38: =-AK143 -> -821.76641 | AL38: =-AL143 -> -899.91682 | AM38: =-AM143 -> -980.98758 | AN38: =-AN143 -> -1064.4454 | AO38: =-AO143 -> -1149.6706 | AP38: =-AP143 -> -1230.2084 | ... AT38: =-AT143 -> -1531.3451
C39: Социальный налог | D39: тыс. тенге | J39: =J155 -> 87.37809 | K39: =K155 -> 87.37809 | L39: =L155 -> 87.37809 | M39: =M155 -> 87.37809 | N39: =N155 -> 87.37809 | O39: =O155 -> 96.545182 | P39: =P155 -> 96.545182 | Q39: =Q155 -> 96.545182 | ... AG39: =AG155 -> 106.19246 | AI39: =-AI155 -> -446.69045 | AJ39: =-AJ155 -> -1184.5318 | AK39: =-AK155 -> -1302.898 | AL39: =-AL155 -> -1426.5907 | AM39: =-AM155 -> -1554.9057 | AN39: =-AN155 -> -1686.9987 | AO39: =-AO155 -> -1821.8891 | AP39: =-AP155 -> -1949.3605 | ... AT39: =-AT155 -> -2425.9853
